<?xml version="1.0" ?>
<!-- =================================================================================== -->
<!-- |    This document was autogenerated by xacro from abb_barrett_robot.xacro        | -->
<!-- |    EDITING THIS FILE BY HAND IS NOT RECOMMENDED                                 | -->
<!-- =================================================================================== -->
<robot name="abb_barrett" xmlns:xacro="http://ros.org/wiki/xacro">
  <!-- Conversion were obtained from http://www.e-paint.co.uk/Lab_values.asp
       unless otherwise stated. -->
  <!-- Actual colors -->
  <!-- NCS 2070-Y60R orange, standard robot color 1974 - May 2014 -->
  <!-- RAL 7035 light grey (abb graphite white), standard robot color May 2014 - current -->
  <!-- RAL 9003 signal white (abb white), cleanroom robot color -->
  <!-- RAL 7032 pebble gray, controller -->
  <!-- RAL 7012 basalt gray (abb dark gray) , robot primer -->
  <!-- RAL 7021 black gray (abb black) , robot with dark link color -->
  <!-- Other robot colours availble, but not limited too. -->
  <!-- RAL 3001 signal red -->
  <!-- RAL 3002 carmine red -->
  <!-- RAL 5002 ultramarine blue -->
  <!-- RAL 5015 sky blue -->
  <!-- RAL 6002 leaf green -->
  <!-- RAL 9002 gray white -->
  <!-- RAL 9010 pure white -->
  <!-- approximations -->
  <!-- yellow, collision model -->
  <gazebo reference="wheel_1">
    <material>Gazebo/Black</material>
    <mu1 value="0.3"/>
    <mu2 value="0.3"/>
  </gazebo>
  <gazebo reference="wheel_2">
    <material>Gazebo/Black</material>
    <mu1 value="0.3"/>
    <mu2 value="0.3"/>
  </gazebo>
  <gazebo reference="wheel_3">
    <material>Gazebo/Black</material>
    <mu1 value="0.3"/>
    <mu2 value="0.3"/>
  </gazebo>
  <gazebo reference="wheel_4">
    <material>Gazebo/Black</material>
    <mu1 value="0.3"/>
    <mu2 value="0.3"/>
  </gazebo>
  <!-- camera_link -->
  <gazebo reference="kinect2_link">
    <sensor name="cam1_frame_sensor" type="depth">
      <always_on>true</always_on>
      <update_rate>20.0</update_rate>
      <camera>
        <horizontal_fov>1.4835298642</horizontal_fov>
        <image>
          <format>R8G8B8</format>
          <width>640</width>
          <height>480</height>
        </image>
        <clip>
          <near>0.01</near>
          <far>5</far>
        </clip>
      </camera>
      <plugin filename="libgazebo_ros_openni_kinect.so" name="cam1_frame_controller">
        <alwaysOn>true</alwaysOn>
        <updateRate>20.0</updateRate>
        <cameraName>kinect2</cameraName>
        <imageTopicName>/ir/image_raw</imageTopicName>
        <cameraInfoTopicName>/ir/camera_info</cameraInfoTopicName>
        <depthImageTopicName>qhd/image_raw</depthImageTopicName>
        <depthImageCameraInfoTopicName>depth/camera_info</depthImageCameraInfoTopicName>
        <pointCloudTopicName>qhd/points</pointCloudTopicName>
        <frameName>kinect2_depth_optical_frame</frameName>
        <pointCloudCutoff>0.5</pointCloudCutoff>
        <distortionK1>0.00000001</distortionK1>
        <distortionK2>0.00000001</distortionK2>
        <distortionK3>0.00000001</distortionK3>
        <distortionT1>0.00000001</distortionT1>
        <distortionT2>0.00000001</distortionT2>
      </plugin>
    </sensor>
    <sensor name="cam2_frame_sensor" type="depth">
      <always_on>true</always_on>
      <update_rate>20.0</update_rate>
      <camera>
        <horizontal_fov>1.4835298642</horizontal_fov>
        <image>
          <format>R8G8B8</format>
          <width>640</width>
          <height>480</height>
        </image>
        <clip>
          <near>0.01</near>
          <far>5</far>
        </clip>
      </camera>
      <plugin filename="libgazebo_ros_openni_kinect.so" name="cam2_frame_controller">
        <alwaysOn>true</alwaysOn>
        <updateRate>20.0</updateRate>
        <cameraName>kinect2</cameraName>
        <imageTopicName>rgb/image_raw</imageTopicName>
        <pointCloudTopicName>depth_registered/points</pointCloudTopicName>
        <cameraInfoTopicName>depth_registered/camera_info</cameraInfoTopicName>
        <frameName>kinect2_rgb_optical_frame</frameName>
        <pointCloudCutoff>0.5</pointCloudCutoff>
        <distortionK1>0.00000001</distortionK1>
        <distortionK2>0.00000001</distortionK2>
        <distortionK3>0.00000001</distortionK3>
        <distortionT1>0.00000001</distortionT1>
        <distortionT2>0.00000001</distortionT2>
      </plugin>
    </sensor>
  </gazebo>
  <joint name="camera_joint" type="fixed">
    <axis xyz="1 0 0"/>
    <origin rpy="0 0 0" xyz="0.042 0 0.01"/>
    <!-- -40 degress-->
    <parent link="camera_frame_link"/>
    <child link="kinect2_link"/>
  </joint>
  <joint name="offset_camera_joint" type="fixed">
    <axis xyz="1 0 0"/>
    <origin rpy="-1.57079632679 0 -1.57079632679" xyz="0 0 -0.05"/>
    <parent link="kinect2_link"/>
    <child link="offset_optical_frame"/>
  </joint>
  <joint name="camera2_joint" type="fixed">
    <axis xyz="1 0 0"/>
    <origin rpy=" -1.57079632679 0 -1.57079632679" xyz="0.0 -0.0 0"/>
    <!--y should be 0 in simulation-->
    <!--y should be -0.11 on robot-->
    <parent link="kinect2_link"/>
    <child link="kinect2_rgb_optical_frame"/>
  </joint>
  <joint name="camera1_joint" type="fixed">
    <axis xyz="1 0 0"/>
    <origin rpy="-1.57079632679 0 -1.57079632679" xyz="0.0 -0.0 0"/>
    <!--y should be 0 in simulation-->
    <!--y should be -0.11 on robot-->
    <parent link="kinect2_link"/>
    <child link="kinect2_depth_optical_frame"/>
  </joint>
  <!-- Camera -->
  <link name="kinect2_link">
    <collision>
      <origin rpy="0 0 -1.57079632679" xyz="-0.12 0.125 -0.04"/>
      <geometry>
        <mesh filename="package://abb_barrett_description/meshes/kinect.STL" scale="0.001 0.001 0.001"/>
        /&gt;
      
      </geometry>
    </collision>
    <visual>
      <origin rpy="0 0 -1.57079632679" xyz="-0.12 0.125 -0.04"/>
      <geometry>
        <mesh filename="package://abb_barrett_description/meshes/kinect.STL" scale="0.001 0.001 0.001"/>
        /&gt;
      
      </geometry>
      <material name="red"/>
    </visual>
    <inertial>
      <mass value="1e-5"/>
      <origin rpy="0 0 0" xyz="0 0 0"/>
      <inertia ixx="1e-6" ixy="0" ixz="0" iyy="1e-6" iyz="0" izz="1e-6"/>
    </inertial>
  </link>
  <link name="kinect2_rgb_optical_frame">
    </link>
  <link name="kinect2_depth_optical_frame">
    </link>
  <link name="offset_optical_frame">
    </link>
  <gazebo reference="kinect2_link">
    <material>Gazebo/Black</material>
    <mu1 value="0.3"/>
    <mu2 value="0.3"/>
    <kp value="1000000.0"/>
    <kd value="1.0"/>
    <minDepth value="1.0"/>
  </gazebo>
  <link name="barrett_base_link">
    <inertial>
      <mass value="0.1"/>
      <origin rpy="0 0 0" xyz="0 0 0"/>
      <inertia ixx="1" ixy="0" ixz="0" iyy="1" iyz="0" izz="1"/>
    </inertial>
    <visual>
      <origin rpy="0 0 0" xyz="0 0 0"/>
      <geometry>
        <mesh filename="package://abb_barrett_description/meshes/base_link.STL"/>
      </geometry>
      <material name="">
        <color rgba="0.752941176470588 0.752941176470588 0.752941176470588 1"/>
      </material>
    </visual>
    <collision>
      <origin rpy="0 0 0" xyz="0 0 0"/>
      <geometry>
        <mesh filename="package://abb_barrett_description/meshes/base_link.STL"/>
      </geometry>
    </collision>
  </link>
  <joint name="palm_joint" type="fixed">
    <!--original is revolute-->
    <origin xyz="0.0 0.0 0.077"/>
    <parent link="barrett_base_link"/>
    <child link="palm_frame"/>
  </joint>
  <link name="palm_frame">
  </link>
  <link name="finger_1_prox_link">
    <inertial>
      <mass value="0.1"/>
      <origin rpy="0 0 0" xyz="0 0 0"/>
      <inertia ixx="1" ixy="0" ixz="0" iyy="1" iyz="0" izz="1"/>
    </inertial>
    <visual>
      <origin rpy="0 0 0" xyz="0 0 0"/>
      <geometry>
        <mesh filename="package://abb_barrett_description/meshes/finger_1_prox_link.STL"/>
      </geometry>
      <material name="">
        <color rgba="0.752941176470588 0.752941176470588 0.752941176470588 1"/>
      </material>
    </visual>
    <collision>
      <origin rpy="0 0 0" xyz="0 0 0"/>
      <geometry>
        <mesh filename="package://abb_barrett_description/meshes/finger_1_prox_link.STL"/>
      </geometry>
    </collision>
  </link>
  <!--joint name="finger_1_prox_joint" type="revolute">
    <origin xyz="0.025 0 0.0415" rpy="0 2.7051E-17 -1.5708" />
    <parent link="barrett_base_link" />
    <child link="finger_1_prox_link" />
    <axis xyz="0 0 -1" />
    <limit lower="0.0" upper="3.141" effort="10000" velocity="0.2" />
   <dynamics damping="10.0" friction="10.0" />
  </joint-->
  <joint name="finger_1_prox_joint" type="revolute">
    <origin rpy="0 2.7051E-17 3.67" xyz="0.025 0 0.0415"/>
    <parent link="barrett_base_link"/>
    <child link="finger_1_prox_link"/>
    <axis xyz="0 0 -1"/>
    <limit effort="10000" lower="0.0" upper="3.141" velocity="0.2"/>
    <dynamics damping="10.0" friction="10.0"/>
  </joint>
  <link name="finger_1_med_link">
    <inertial>
      <mass value="0.1"/>
      <origin rpy="0 0 0" xyz="0 0 0"/>
      <inertia ixx="1" ixy="0" ixz="0" iyy="1" iyz="0" izz="1"/>
    </inertial>
    <visual>
      <origin rpy="3.14159265359 0 0" xyz="0 0 0"/>
      <geometry>
        <mesh filename="package://abb_barrett_description/meshes/finger_1_med_link.STL"/>
      </geometry>
      <material name="">
        <color rgba="0.752941176470588 0.752941176470588 0.752941176470588 1"/>
      </material>
    </visual>
    <collision>
      <origin rpy="3.14159265359 0 0" xyz="0 0 0"/>
      <geometry>
        <mesh filename="package://abb_barrett_description/meshes/finger_1_med_link.STL"/>
      </geometry>
    </collision>
  </link>
  <!--joint
    name="finger_1_med_joint"
    type="revolute">
    <origin xyz="-0.05 0 0.0339" rpy="-1.5708 -8.8281E-17 0" />
    <parent link="finger_1_prox_link" />
    <child link="finger_1_med_link" />
    <axis xyz="0 0 1" />
    <limit lower="0" upper="2.44" effort="10000" velocity="0.2" />
   <dynamics damping="10.0" friction="10.0" />
  </joint-->
  <joint name="finger_1_med_joint" type="revolute">
    <origin rpy="-1.5708 1.5708 0" xyz="-0.05 0 0.0339"/>
    <parent link="finger_1_prox_link"/>
    <child link="finger_1_med_link"/>
    <axis xyz="0 0 1"/>
    <limit effort="10000" lower="0" upper="2.44" velocity="0.2"/>
    <dynamics damping="10.0" friction="10.0"/>
  </joint>
  <link name="finger_1_dist_link">
    <inertial>
      <mass value="0.001"/>
      <origin rpy="0 0 0" xyz="0 0 0"/>
      <inertia ixx="1e-1" ixy="0" ixz="0" iyy="1e-1" iyz="0" izz="1e-1"/>
    </inertial>
    <visual>
      <origin rpy="3.14159265359 0 -0.73" xyz="0 0 0"/>
      <geometry>
        <mesh filename="package://abb_barrett_description/meshes/finger_1_dist_link.STL"/>
      </geometry>
      <material name="">
        <color rgba="0.898039215686275 0.917647058823529 0.929411764705882 1"/>
      </material>
    </visual>
    <collision>
      <origin rpy="3.14159265359 0 -0.73" xyz="0 0 0"/>
      <geometry>
        <mesh filename="package://abb_barrett_description/meshes/finger_1_dist_link.STL"/>
      </geometry>
    </collision>
  </link>
  <joint name="finger_1_dist_joint" type="revolute">
    <!--original is revolute-->
    <origin rpy="1.6787E-18 -3.6382E-15 -6.1073E-33" xyz="-0.069936 -0.003 0"/>
    <parent link="finger_1_med_link"/>
    <child link="finger_1_dist_link"/>
    <axis xyz="0 0 1"/>
    <limit effort="10000" lower="0.6" upper="1.57" velocity="0.2"/>
    <dynamics damping="10.0" friction="10.0"/>
    <mimic joint="finger_1_med_joint" multiplier="0.3" offset="0.75"/>
  </joint>
  <link name="finger_2_prox_link">
    <inertial>
      <mass value="0.1"/>
      <origin rpy="0 0 0" xyz="0 0 0"/>
      <inertia ixx="1" ixy="0" ixz="0" iyy="1" iyz="0" izz="1"/>
    </inertial>
    <visual>
      <origin rpy="0 0 0" xyz="0 0 0"/>
      <geometry>
        <mesh filename="package://abb_barrett_description/meshes/finger_2_prox_link.STL"/>
      </geometry>
      <material name="">
        <color rgba="0.752941176470588 0.752941176470588 0.752941176470588 1"/>
      </material>
    </visual>
    <collision>
      <origin rpy="0 0 0" xyz="0 0 0"/>
      <geometry>
        <mesh filename="package://abb_barrett_description/meshes/finger_2_prox_link.STL"/>
      </geometry>
    </collision>
  </link>
  <!--joint name="finger_2_prox_joint" type="revolute">
    <origin xyz="-0.025 0 0.0415" rpy="0 2.7051E-17 -1.5708" />
    <parent link="barrett_base_link" />
    <child link="finger_2_prox_link" />
    <axis xyz="0 0 1" />
    <limit lower="0" upper="3.141" effort="10000"  velocity="0.2" />
   <dynamics damping="10.0" friction="10.0" />
  </joint-->
  <joint name="finger_2_prox_joint" type="revolute">
    <origin rpy="0 2.7051E-17 -0.52" xyz="-0.025 0 0.0415"/>
    <parent link="barrett_base_link"/>
    <child link="finger_2_prox_link"/>
    <axis xyz="0 0 1"/>
    <limit effort="10000" lower="0" upper="3.141" velocity="0.2"/>
    <dynamics damping="10.0" friction="10.0"/>
  </joint>
  <link name="finger_2_med_link">
    <inertial>
      <mass value="0.1"/>
      <origin rpy="0 0 0" xyz="0 0 0"/>
      <inertia ixx="1" ixy="0" ixz="0" iyy="1" iyz="0" izz="1"/>
    </inertial>
    <visual>
      <origin rpy="3.14159265359 0 0" xyz="0 0 0"/>
      <geometry>
        <mesh filename="package://abb_barrett_description/meshes/finger_2_med_link.STL"/>
      </geometry>
      <material name="">
        <color rgba="0.752941176470588 0.752941176470588 0.752941176470588 1"/>
      </material>
    </visual>
    <collision>
      <origin rpy="3.14159265359 0 0" xyz="0 0 0"/>
      <geometry>
        <mesh filename="package://abb_barrett_description/meshes/finger_2_med_link.STL"/>
      </geometry>
    </collision>
  </link>
  <!--joint
    name="finger_2_med_joint"
    type="revolute">
    <origin xyz="-0.05 0 0.0339" rpy="-1.5708 -8.8281E-17 0" />
    <parent link="finger_2_prox_link" />
    <child link="finger_2_med_link" />
    <axis xyz="0 0 1" />
    <limit lower="0.0" upper="2.44" effort="10000" velocity="0.2" />
   <dynamics damping="10.0" friction="10.0" />
  </joint-->
  <joint name="finger_2_med_joint" type="revolute">
    <origin rpy="-1.5708 1.5708 0" xyz="-0.05 0 0.0339"/>
    <parent link="finger_2_prox_link"/>
    <child link="finger_2_med_link"/>
    <axis xyz="0 0 1"/>
    <limit effort="10000" lower="0.0" upper="2.44" velocity="0.2"/>
    <dynamics damping="10.0" friction="10.0"/>
  </joint>
  <link name="finger_2_dist_link">
    <inertial>
      <mass value="0.001"/>
      <origin rpy="0 0 0" xyz="0 0 0"/>
      <inertia ixx="1e-1" ixy="0" ixz="0" iyy="1e-1" iyz="0" izz="1e-1"/>
    </inertial>
    <visual>
      <origin rpy="3.14159265359 0 -0.73" xyz="0 0 0"/>
      <geometry>
        <mesh filename="package://abb_barrett_description/meshes/finger_2_dist_link.STL"/>
      </geometry>
      <material name="">
        <color rgba="0.898039215686275 0.917647058823529 0.929411764705882 1"/>
      </material>
    </visual>
    <collision>
      <origin rpy="3.14159265359 0 -0.73" xyz="0 0 0"/>
      <geometry>
        <mesh filename="package://abb_barrett_description/meshes/finger_2_dist_link.STL"/>
      </geometry>
    </collision>
  </link>
  <joint name="finger_2_dist_joint" type="revolute">
    <!--original is revolute-->
    <origin rpy="-3.1382E-17 -2.3229E-16 0" xyz="-0.069917 -0.0034087 0"/>
    <parent link="finger_2_med_link"/>
    <child link="finger_2_dist_link"/>
    <axis xyz="0 0 1"/>
    <limit effort="10000" lower="0.6" upper="1.57" velocity="0.2"/>
    <dynamics damping="10.0" friction="10.0"/>
    <mimic joint="finger_2_med_joint" multiplier="0.3" offset="0.75"/>
  </joint>
  <link name="finger_3_med_link">
    <inertial>
      <mass value="0.1"/>
      <origin rpy="0 0 0" xyz="-0.05 0 0"/>
      <inertia ixx="1" ixy="0" ixz="0" iyy="1" iyz="0" izz="1"/>
    </inertial>
    <visual>
      <origin rpy="3.14159265359 0 0" xyz="0 0 0"/>
      <geometry>
        <mesh filename="package://abb_barrett_description/meshes/finger_3_med_link.STL"/>
      </geometry>
      <material name="">
        <color rgba="0.752941176470588 0.752941176470588 0.752941176470588 1"/>
      </material>
    </visual>
    <collision>
      <origin rpy="3.14159265359 0 0" xyz="0 0 0"/>
      <geometry>
        <mesh filename="package://abb_barrett_description/meshes/finger_3_med_link.STL"/>
      </geometry>
    </collision>
  </link>
  <!--joint
    name="finger_3_med_joint"
    type="revolute">
    <origin
      xyz="0 -0.05 0.0754"
      rpy="-1.5708 6.123E-17 1.5708" />
    <parent
      link="barrett_base_link" />
    <child
      link="finger_3_med_link" />
    <axis
      xyz="0 0 1" />
    <limit
      lower="0.0"
      upper="2.44"
      effort="10000"
      velocity="0.2" />
   <dynamics damping="10.0" friction="10.0" />
  </joint-->
  <joint name="finger_3_med_joint" type="revolute">
    <origin rpy="-1.5708 1.5708 1.5708" xyz="0 -0.05 0.0754"/>
    <parent link="barrett_base_link"/>
    <child link="finger_3_med_link"/>
    <axis xyz="0 0 1"/>
    <limit effort="10000" lower="0.0" upper="2.44" velocity="0.2"/>
    <dynamics damping="10.0" friction="10.0"/>
  </joint>
  <link name="finger_3_dist_link">
    <inertial>
      <mass value="0.1"/>
      <origin rpy="0 0 0" xyz="-0.04 0 0"/>
      <inertia ixx="1" ixy="0" ixz="0" iyy="1" iyz="0" izz="1"/>
    </inertial>
    <visual>
      <origin rpy="3.14159265359 0 -0.73" xyz="0 0 0"/>
      <geometry>
        <mesh filename="package://abb_barrett_description/meshes/finger_3_dist_link.STL"/>
      </geometry>
      <material name="">
        <color rgba="0.898039215686275 0.917647058823529 0.929411764705882 1"/>
      </material>
    </visual>
    <collision>
      <origin rpy="3.14159265359 0 -0.73" xyz="0 0 0"/>
      <geometry>
        <mesh filename="package://abb_barrett_description/meshes/finger_3_dist_link.STL"/>
      </geometry>
    </collision>
  </link>
  <joint name="finger_3_dist_joint" type="revolute">
    <!--original is revolute-->
    <origin rpy="6.0427E-17 -6.7283E-18 -4.0657E-34" xyz="-0.069936 -0.003 0"/>
    <parent link="finger_3_med_link"/>
    <child link="finger_3_dist_link"/>
    <axis xyz="0 0 1"/>
    <limit effort="10000" lower="0.6" upper="1.57" velocity="0.2"/>
    <dynamics damping="10.0" friction="10.0"/>
    <mimic joint="finger_3_med_joint" multiplier="0.3" offset="0.75"/>
  </joint>
  <transmission name="tran11">
    <type>transmission_interface/SimpleTransmission</type>
    <joint name="finger_1_med_joint">
      <hardwareInterface>PositionJointInterface</hardwareInterface>
    </joint>
    <actuator name="motor11">
      <hardwareInterface>PositionJointInterface</hardwareInterface>
      <mechanicalReduction>1</mechanicalReduction>
    </actuator>
  </transmission>
  <transmission name="tran12">
    <type>transmission_interface/SimpleTransmission</type>
    <joint name="finger_1_dist_joint">
      <hardwareInterface>PositionJointInterface</hardwareInterface>
    </joint>
    <actuator name="motor12">
      <hardwareInterface>PositionJointInterface</hardwareInterface>
      <mechanicalReduction>1</mechanicalReduction>
    </actuator>
  </transmission>
  <transmission name="tran13">
    <type>transmission_interface/SimpleTransmission</type>
    <joint name="finger_2_med_joint">
      <hardwareInterface>PositionJointInterface</hardwareInterface>
    </joint>
    <actuator name="motor13">
      <hardwareInterface>PositionJointInterface</hardwareInterface>
      <mechanicalReduction>1</mechanicalReduction>
    </actuator>
  </transmission>
  <transmission name="tran14">
    <type>transmission_interface/SimpleTransmission</type>
    <joint name="finger_2_dist_joint">
      <hardwareInterface>PositionJointInterface</hardwareInterface>
    </joint>
    <actuator name="motor14">
      <hardwareInterface>PositionJointInterface</hardwareInterface>
      <mechanicalReduction>10</mechanicalReduction>
    </actuator>
  </transmission>
  <transmission name="tran15">
    <type>transmission_interface/SimpleTransmission</type>
    <joint name="finger_3_med_joint">
      <hardwareInterface>PositionJointInterface</hardwareInterface>
    </joint>
    <actuator name="motor15">
      <hardwareInterface>PositionJointInterface</hardwareInterface>
      <mechanicalReduction>1</mechanicalReduction>
    </actuator>
  </transmission>
  <transmission name="tran16">
    <type>transmission_interface/SimpleTransmission</type>
    <joint name="finger_3_dist_joint">
      <hardwareInterface>PositionJointInterface</hardwareInterface>
    </joint>
    <actuator name="motor16">
      <hardwareInterface>PositionJointInterface</hardwareInterface>
      <mechanicalReduction>1</mechanicalReduction>
    </actuator>
  </transmission>
  <transmission name="tran17">
    <type>transmission_interface/SimpleTransmission</type>
    <joint name="finger_1_prox_joint">
      <hardwareInterface>PositionJointInterface</hardwareInterface>
    </joint>
    <actuator name="motor17">
      <hardwareInterface>PositionJointInterface</hardwareInterface>
      <mechanicalReduction>1</mechanicalReduction>
    </actuator>
  </transmission>
  <transmission name="tran18">
    <type>transmission_interface/SimpleTransmission</type>
    <joint name="finger_2_prox_joint">
      <hardwareInterface>PositionJointInterface</hardwareInterface>
    </joint>
    <actuator name="motor18">
      <hardwareInterface>PositionJointInterface</hardwareInterface>
      <mechanicalReduction>1</mechanicalReduction>
    </actuator>
  </transmission>
  <!-- base_link -->
  <gazebo reference="barrett_base_link">
    <material>Gazebo/Orange</material>
    <turnGravityOff>true</turnGravityOff>
  </gazebo>
  <!-- finger_1_prox_link -->
  <gazebo reference="finger_1_prox_link">
    <material>Gazebo/Orange</material>
    <turnGravityOff>true</turnGravityOff>
    <mu1 value="1500.0"/>
    <mu2 value="1500.0"/>
    <kp value="1000000.0"/>
    <kd value="1.0"/>
  </gazebo>
  <gazebo reference="finger_1_prox_joint">
    <stopKd value="1.0"/>
    <stopKp value="10000000.0"/>
    <fudgeFactor value="1.0"/>
    <provideFeedback value="true"/>
  </gazebo>
  <!-- finger_1_med_link -->
  <gazebo reference="finger_1_med_link">
    <turnGravityOff>true</turnGravityOff>
    <mu1 value="1500.0"/>
    <mu2 value="1500.0"/>
    <kp value="1000000.0"/>
    <kd value="1.0"/>
    <material>Gazebo/Black</material>
  </gazebo>
  <gazebo reference="finger_1_med_joint">
    <stopKd value="1.0"/>
    <stopKp value="10000000.0"/>
    <fudgeFactor value="1.0"/>
    <provideFeedback value="true"/>
  </gazebo>
  <!-- finger_1_dist_link -->
  <gazebo reference="finger_1_dist_link">
    <turnGravityOff>true</turnGravityOff>
    <mu1 value="1500.0"/>
    <mu2 value="1500.0"/>
    <kp value="1000000.0"/>
    <kd value="1.0"/>
    <material>Gazebo/Orange</material>
  </gazebo>
  <gazebo reference="finger_1_dist_joint">
    <stopKd value="1.0"/>
    <stopKp value="10000000.0"/>
    <fudgeFactor value="1.0"/>
    <provideFeedback value="true"/>
  </gazebo>
  <!-- finger_2_prox_link -->
  <gazebo reference="finger_2_prox_link">
    <turnGravityOff>true</turnGravityOff>
    <mu1 value="1500.0"/>
    <mu2 value="1500.0"/>
    <kp value="1000000.0"/>
    <kd value="1.0"/>
    <material>Gazebo/Orange</material>
  </gazebo>
  <!-- finger_2_med_link -->
  <gazebo reference="finger_2_med_link">
    <turnGravityOff>true</turnGravityOff>
    <mu1 value="1500.0"/>
    <mu2 value="1500.0"/>
    <kp value="1000000.0"/>
    <kd value="1.0"/>
    <material>Gazebo/Black</material>
  </gazebo>
  <!-- finger_2_dist_link -->
  <gazebo reference="finger_2_dist_link">
    <turnGravityOff>true</turnGravityOff>
    <mu1 value="1500.0"/>
    <mu2 value="1500.0"/>
    <kp value="1000000.0"/>
    <kd value="1.0"/>
    <material>Gazebo/Orange</material>
  </gazebo>
  <!-- finger_3_med_link -->
  <gazebo reference="finger_3_med_link">
    <turnGravityOff>true</turnGravityOff>
    <mu1 value="1500.0"/>
    <mu2 value="1500.0"/>
    <kp value="1000000.0"/>
    <kd value="1.0"/>
    <material>Gazebo/Black</material>
  </gazebo>
  <!-- finger_3_dist_link -->
  <gazebo reference="finger_3_dist_link">
    <turnGravityOff>true</turnGravityOff>
    <mu1 value="1500.0"/>
    <mu2 value="1500.0"/>
    <kp value="1000000.0"/>
    <kd value="1.0"/>
    <material>Gazebo/Orange</material>
  </gazebo>
  <gazebo>
    <plugin filename="libgazebo_ros_p3d.so" name="p3d_barrett_gripper_palm_controller">
      <alwaysOn>true</alwaysOn>
      <updateRate>100.0</updateRate>
      <bodyName>barrett_base_link</bodyName>
      <topicName>barrett_palm_pose_ground_truth</topicName>
      <xyzOffsets>0 0 0</xyzOffsets>
      <rpyOffsets>0 0 0</rpyOffsets>
      <gaussianNoise>0.0</gaussianNoise>
      <frameName>world</frameName>
    </plugin>
    <!-- a formal implementation of grasp hack in gazebo with fixed joint -->
    <gripper name="barrett_grasp_hack">
      <grasp_check>
        <attach_steps>20</attach_steps>
        <detach_steps>40</detach_steps>
        <min_contact_count>2</min_contact_count>
      </grasp_check>
      <gripper_link>finger_1_prox_link</gripper_link>
      <gripper_link>finger_2_prox_link</gripper_link>
      <palm_link>barrett_base_link</palm_link>
    </gripper>
  </gazebo>
  <gazebo>
    <plugin filename="libgazebo_mimic_plugin.so" name="mimic_plugin">
      <joint>finger_1_med_joint</joint>
      <mimicJoint>finger_1_dist_joint</mimicJoint>
      <multiplier>1.0</multiplier>
    </plugin>
  </gazebo>
  <gazebo>
    <plugin filename="libgazebo_mimic_plugin.so" name="mimic_plugin">
      <joint>finger_2_med_joint</joint>
      <mimicJoint>finger_2_dist_joint</mimicJoint>
      <multiplier>1.0</multiplier>
    </plugin>
  </gazebo>
  <gazebo>
    <plugin filename="libgazebo_mimic_plugin.so" name="mimic_plugin">
      <joint>finger_3_med_joint</joint>
      <mimicJoint>finger_3_dist_joint</mimicJoint>
      <multiplier>1.0</multiplier>
    </plugin>
  </gazebo>
  <!--<gazebo>
    <plugin name="gazebo_ros_control" filename="libgazebo_ros_control.so">
      <robotNamespace>/</robotNamespace>
      <robotSimType>gazebo_ros_control/DefaultRobotHWSim</robotSimType>
    </plugin>
  </gazebo>-->
  <gazebo>
    <plugin filename="libgazebo_ros_joint_pose_trajectory.so" name="gazebo_ros_joint_trajectory">
      <robotNamespace>/</robotNamespace>
      <alwaysOn>true</alwaysOn>
      <updateRate>100.0</updateRate>
    </plugin>
  </gazebo>
  <gazebo reference="hokuyo_link">
    <sensor name="head_hokuyo_sensor" type="gpu_ray">
      <pose>0 0 0 0 0 0</pose>
      <visualize>true</visualize>
      <update_rate>40</update_rate>
      <ray>
        <scan>
          <horizontal>
            <samples>720</samples>
            <resolution>1</resolution>
            <min_angle>-1.48353</min_angle>
            <max_angle>1.48353</max_angle>
          </horizontal>
        </scan>
        <range>
          <min>0.10</min>
          <max>30.0</max>
          <resolution>0.01</resolution>
        </range>
        <noise>
          <type>gaussian</type>
          <!-- Noise parameters based on published spec for Hokuyo laser
               achieving "+-30mm" accuracy at range < 10m.  A mean of 0.0m and
               stddev of 0.01m will put 99.7% of samples within 0.03m of the true
               reading. -->
          <mean>0.0</mean>
          <stddev>0.01</stddev>
        </noise>
      </ray>
      <plugin filename="libgazebo_ros_gpu_laser.so" name="gazebo_ros_head_hokuyo_controller">
        <topicName>/scan</topicName>
        <frameName>hokuyo_link</frameName>
      </plugin>
    </sensor>
  </gazebo>
  <!-- Hokuyo Laser -->
  <link name="hokuyo_link">
    <collision>
      <origin rpy="0 0 0" xyz="0 0 0"/>
      <geometry>
        <box size="0.1 0.1 0.1"/>
      </geometry>
    </collision>
    <visual>
      <origin rpy="0 0 0" xyz="0 0 0"/>
      <geometry>
        <cylinder length="0.04" radius="0.02"/>
      </geometry>
    </visual>
    <inertial>
      <mass value="1e-5"/>
      <origin rpy="0 0 0" xyz="0 0 0"/>
      <inertia ixx="1e-6" ixy="0" ixz="0" iyy="1e-6" iyz="0" izz="1e-6"/>
    </inertial>
  </link>
  <gazebo reference="hokuyo_link">
    <material>Gazebo/Black</material>
    <mu1 value="0.3"/>
    <mu2 value="0.3"/>
    <kp value="1000000.0"/>
    <kd value="1.0"/>
    <minDepth value="1.0"/>
  </gazebo>
  <link name="cylinder_link">
    <inertial>
      <origin xyz="0 0 0"/>
      <mass value="0.057"/>
      <inertia ixx="169.31e-7" ixy="0.0" ixz="0.0" iyy="102.35e-7" iyz="0.0" izz="169.31e-7"/>
    </inertial>
    <visual>
      <origin xyz="0 0 0"/>
      <geometry>
        <mesh filename="package://models/peg_in_hole/circle.STL"/>
      </geometry>
    </visual>
    <collision>
      <origin xyz="0 0 0 "/>
      <geometry>
        <mesh filename="package://models/peg_in_hole/circle.STL"/>
      </geometry>
    </collision>
  </link>
  <gazebo reference="cylinder_link">
    <material>Gazebo/Black</material>
    <mu1 value="0.3"/>
    <mu2 value="0.3"/>
    <kp value="1000000.0"/>
    <kd value="1.0"/>
    <minDepth value="1.0"/>
  </gazebo>
  <link name="cube_link">
    <inertial>
      <origin xyz="0 0 0"/>
      <mass value="0.25"/>
      <inertia ixx="15563.41e-7" ixy="-0.07e-7" ixz="5.91e-7" iyy="15482.20e-7" iyz="1.06e-7" izz="15507.44e-7"/>
    </inertial>
    <visual>
      <origin xyz="0 0 0"/>
      <geometry>
        <mesh filename="package://models/peg_in_hole/Cube.STL"/>
      </geometry>
    </visual>
    <collision>
      <origin xyz="0 0 0 "/>
      <geometry>
        <mesh filename="package://models/peg_in_hole/Cube.STL"/>
      </geometry>
    </collision>
  </link>
  <gazebo reference="cube_link">
    <material>Gazebo/White</material>
    <mu1 value="0.3"/>
    <mu2 value="0.3"/>
    <kp value="1000000.0"/>
    <kd value="1.0"/>
    <minDepth value="1.0"/>
    <selfCollide>true</selfCollide>
  </gazebo>
  <!-- get base ABB IRB120 model -->
  <!-- link list -->
  <link name="base_link_robot">
    <inertial>
      <mass value="110"/>
      <origin rpy="0 0 0" xyz="0.05 -0.01 -0.48"/>
      <inertia ixx="100" ixy="-0.01" ixz="-1.19" iyy="100" iyz="0.02" izz="6.5"/>
    </inertial>
    <visual>
      <origin rpy="0 0 0" xyz="0.05 -0.01 -0.22"/>
      <geometry>
        <mesh filename="package://abb_barrett_support/meshes/abb_barrett/visual/Final_Assembly.STL"/>
      </geometry>
      <material name="">
        <color rgba="0.7372549 0.3490196 0.1607843 1"/>
      </material>
    </visual>
    <collision>
      <origin rpy="0 0 0" xyz="-0 0 -0.1 "/>
      <!--origin xyz="-0.18 -0.37 -0.35" rpy="0 0 0"/-->
      <geometry>
        <box size="0.7 0.5 0.3"/>
        <!--mesh filename="package://abb_barrett_support/meshes/abb_barrett/collision/Final_Assembly.STL" scale="0.001 0.001 0.001"/-->
      </geometry>
      <material name="">
        <color rgba="1 1 0 1"/>
      </material>
    </collision>
    <collision>
      <origin rpy="0 0 0" xyz="-0.17 0 0.5 "/>
      <!--origin xyz="-0.18 -0.37 -0.35" rpy="0 0 0"/-->
      <geometry>
        <box size="0.7 0.5 0.9"/>
        <!--mesh filename="package://abb_barrett_support/meshes/abb_barrett/collision/Final_Assembly.STL" scale="0.001 0.001 0.001"/-->
      </geometry>
      <material name="">
        <color rgba="1 1 0 1"/>
      </material>
    </collision>
  </link>
  <link name="wheel_1">
    <inertial>
      <mass value="0.5"/>
      <origin xyz="0 0 0.0"/>
      <inertia ixx="1e-5" ixy="0" ixz="0" iyy="1e-5" iyz="0" izz="1e-5"/>
    </inertial>
    <visual>
      <origin xyz="0 0 0.0"/>
      <geometry>
        <cylinder length="0.08" radius="0.04"/>
      </geometry>
      <material name="">
        <color rgba="0.7372549 0.3490196 0.1607843 1"/>
      </material>
    </visual>
    <collision>
      <origin xyz="0 0 0.0"/>
      <geometry>
        <cylinder length="0.08" radius="0.04"/>
      </geometry>
      <material name="">
        <color rgba="1 1 0 1"/>
      </material>
    </collision>
  </link>
  <link name="wheel_2">
    <inertial>
      <mass value="0.5"/>
      <origin xyz="0 0 0.0"/>
      <inertia ixx="1e-5" ixy="0" ixz="0" iyy="1e-5" iyz="0" izz="1e-5"/>
    </inertial>
    <visual>
      <origin xyz="0 0 0.0"/>
      <geometry>
        <cylinder length="0.08" radius="0.04"/>
      </geometry>
      <material name="">
        <color rgba="0.7372549 0.3490196 0.1607843 1"/>
      </material>
    </visual>
    <collision>
      <origin xyz="0 0 0.0"/>
      <geometry>
        <cylinder length="0.08" radius="0.04"/>
      </geometry>
      <material name="">
        <color rgba="1 1 0 1"/>
      </material>
    </collision>
  </link>
  <link name="wheel_3">
    <inertial>
      <mass value="0.5"/>
      <origin xyz="0 0 0.0"/>
      <inertia ixx="1e-5" ixy="0" ixz="0" iyy="1e-5" iyz="0" izz="1e-5"/>
    </inertial>
    <visual>
      <origin xyz="0 0 0.0"/>
      <geometry>
        <cylinder length="0.08" radius="0.04"/>
      </geometry>
      <material name="">
        <color rgba="0.7372549 0.3490196 0.1607843 1"/>
      </material>
    </visual>
    <collision>
      <origin xyz="0 0 0.0"/>
      <geometry>
        <cylinder length="0.08" radius="0.04"/>
      </geometry>
      <material name="">
        <color rgba="1 1 0 1"/>
      </material>
    </collision>
  </link>
  <link name="wheel_4">
    <inertial>
      <mass value="0.5"/>
      <origin xyz="0 0 0.0"/>
      <inertia ixx="1e-5" ixy="0" ixz="0" iyy="1e-5" iyz="0" izz="1e-5"/>
    </inertial>
    <visual>
      <origin xyz="0 0 0.0"/>
      <geometry>
        <cylinder length="0.08" radius="0.04"/>
      </geometry>
      <material name="">
        <color rgba="0.7372549 0.3490196 0.1607843 1"/>
      </material>
    </visual>
    <collision>
      <origin xyz="0 0 0.0"/>
      <geometry>
        <cylinder length="0.08" radius="0.04"/>
      </geometry>
      <material name="">
        <color rgba="1 1 0 1"/>
      </material>
    </collision>
  </link>
  <link name="base_link">
    <inertial>
      <!-- <mass value="6.215"/>-->
      <mass value="0.01"/>
      <origin rpy="0 0 0" xyz="-0.04204 8.01E-05 0.07964"/>
      <inertia ixx="0.0247272" ixy="-8.0784E-05" ixz="0.00130902" iyy="0.0491285" iyz="-8.0419E-06" izz="0.0472376"/>
    </inertial>
    <visual>
      <origin rpy="0 0 0" xyz="0 0 0"/>
      <geometry>
        <mesh filename="package://abb_barrett_support/meshes/abb_barrett/visual/base_link.stl"/>
      </geometry>
      <material name="">
        <color rgba="0.7372549 0.3490196 0.1607843 1"/>
      </material>
    </visual>
    <collision>
      <origin rpy="0 0 0" xyz="0 0 0"/>
      <geometry>
        <mesh filename="package://abb_barrett_support/meshes/abb_barrett/collision/base_link.stl"/>
      </geometry>
      <material name="">
        <color rgba="1 1 0 1"/>
      </material>
    </collision>
  </link>
  <link name="link_1">
    <inertial>
      <!--<mass value="3.067" />-->
      <mass value="0.001"/>
      <origin rpy="0 0 0" xyz="9.77E-05 -0.00012 0.23841"/>
      <inertia ixx="0.0142175" ixy="-1.28579E-05" ixz="-2.31364E-05" iyy="0.0144041" iyz="1.93404E-05" izz="0.0104533"/>
    </inertial>
    <visual>
      <origin rpy="0 0 0" xyz="0 0 0"/>
      <geometry>
        <mesh filename="package://abb_barrett_support/meshes/abb_barrett/visual/link_1.stl"/>
      </geometry>
      <material name="">
        <color rgba="0.7372549 0.3490196 0.1607843 1"/>
      </material>
    </visual>
    <collision>
      <origin rpy="0 0 0" xyz="0 0 0"/>
      <geometry>
        <mesh filename="package://abb_barrett_support/meshes/abb_barrett/collision/link_1.stl"/>
      </geometry>
      <material name="">
        <color rgba="1 1 0 1"/>
      </material>
    </collision>
  </link>
  <link name="link_2">
    <inertial>
      <!--<mass value="3.909"/>-->
      <mass value="0.001"/>
      <origin rpy="0 0 0" xyz="0.00078 -0.00212 0.10124"/>
      <inertia ixx="0.0603111" ixy="9.83431E-06" ixz="5.72407E-05" iyy="0.041569" iyz="-0.00050497" izz="0.0259548"/>
    </inertial>
    <visual>
      <origin rpy="0 0 0" xyz="0 0 0"/>
      <geometry>
        <mesh filename="package://abb_barrett_support/meshes/abb_barrett/visual/link_2.stl"/>
      </geometry>
      <material name="">
        <color rgba="0.7372549 0.3490196 0.1607843 1"/>
      </material>
    </visual>
    <collision>
      <origin rpy="0 0 0" xyz="0 0 0"/>
      <geometry>
        <mesh filename="package://abb_barrett_support/meshes/abb_barrett/collision/link_2.stl"/>
      </geometry>
      <material name="">
        <color rgba="1 1 0 1"/>
      </material>
    </collision>
  </link>
  <link name="link_3">
    <inertial>
      <!--<mass value="2.944"/>-->
      <mass value="0.001"/>
      <origin rpy="0 0 0" xyz="0.02281 0.00106 0.05791"/>
      <inertia ixx="0.00835606" ixy="-8.01545E-05" ixz="0.00142884" iyy="0.016713" iyz="-0.000182227" izz="0.0126984"/>
    </inertial>
    <visual>
      <origin rpy="0 0 0" xyz="0 0 0"/>
      <geometry>
        <mesh filename="package://abb_barrett_support/meshes/abb_barrett/visual/link_3.stl"/>
      </geometry>
      <material name="">
        <color rgba="0.7372549 0.3490196 0.1607843 1"/>
      </material>
    </visual>
    <collision>
      <origin rpy="0 0 0" xyz="0 0 0"/>
      <geometry>
        <mesh filename="package://abb_barrett_support/meshes/abb_barrett/collision/link_3.stl"/>
      </geometry>
      <material name="">
        <color rgba="1 1 0 1"/>
      </material>
    </collision>
  </link>
  <link name="link_4">
    <inertial>
      <!--<mass value="1.328"/>-->
      <mass value="0.001"/>
      <origin rpy="0 0 0" xyz="0.2247 0.00015 0.00041"/>
      <inertia ixx="0.00284661" ixy="-2.12765E-05" ixz="-1.6435E-05" iyy="0.00401346" iyz="1.31336E-05" izz="0.0052535"/>
    </inertial>
    <visual>
      <origin rpy="0 0 0" xyz="0 0 0"/>
      <geometry>
        <mesh filename="package://abb_barrett_support/meshes/abb_barrett/visual/link_4.stl"/>
      </geometry>
      <material name="">
        <color rgba="0.7372549 0.3490196 0.1607843 1"/>
      </material>
    </visual>
    <collision>
      <origin rpy="0 0 0" xyz="0 0 0"/>
      <geometry>
        <mesh filename="package://abb_barrett_support/meshes/abb_barrett/collision/link_4.stl"/>
      </geometry>
      <material name="">
        <color rgba="1 1 0 1"/>
      </material>
    </collision>
  </link>
  <link name="link_5">
    <inertial>
      <!--<mass value="0.546"/>-->
      <mass value="0.001"/>
      <origin rpy="0 0 0" xyz="-0.00109 3.68E-05 6.22E-05"/>
      <inertia ixx="0.000404891" ixy="1.61943E-06" ixz="8.46805E-07" iyy="0.000892825" iyz="-1.51792E-08" izz="0.000815468"/>
    </inertial>
    <visual>
      <origin rpy="0 0 0" xyz="0 0 0"/>
      <geometry>
        <mesh filename="package://abb_barrett_support/meshes/abb_barrett/visual/link_5.stl"/>
      </geometry>
      <material name="">
        <color rgba="0.7372549 0.3490196 0.1607843 1"/>
      </material>
    </visual>
    <collision>
      <origin rpy="0 0 0" xyz="0 0 0"/>
      <geometry>
        <mesh filename="package://abb_barrett_support/meshes/abb_barrett/collision/link_5.stl"/>
      </geometry>
      <material name="">
        <color rgba="1 1 0 1"/>
      </material>
    </collision>
  </link>
  <link name="link_6">
    <inertial>
      <!--<mass value="0.137"/>-->
      <mass value="0.001"/>
      <origin rpy="0 0 0" xyz="-0.00706 -0.00017 -1.32E-06"/>
      <inertia ixx="0.001" ixy="0" ixz="0" iyy="0.001" iyz="0" izz="0.001"/>
    </inertial>
    <visual>
      <origin rpy="0 0 0" xyz="0 0 0"/>
      <geometry>
        <mesh filename="package://abb_barrett_support/meshes/abb_barrett/visual/link_6.stl"/>
      </geometry>
      <material name="">
        <color rgba="0.1882353 0.1960784 0.2039216 1"/>
      </material>
    </visual>
    <collision>
      <origin rpy="0 0 0" xyz="0 0 0"/>
      <geometry>
        <mesh filename="package://abb_barrett_support/meshes/abb_barrett/collision/link_6.stl"/>
      </geometry>
      <material name="">
        <color rgba="1 1 0 1"/>
      </material>
    </collision>
  </link>
  <link name="camera_frame_link">
    <inertial>
      <mass value="0.5"/>
      <origin rpy="0 0 0" xyz="0 0 0"/>
      <inertia ixx="0.001" ixy="0" ixz="0" iyy="0.001" iyz="0" izz="0.001"/>
    </inertial>
    <visual>
      <origin rpy="0 0 0" xyz="0 0 +0.001"/>
      <geometry>
        <mesh filename="package://abb_barrett_support/meshes/abb_barrett/visual/camera_frame_link.STL"/>
      </geometry>
      <material name="">
        <color rgba="0.1882353 0.1960784 0.2039216 1"/>
      </material>
    </visual>
    <collision>
      <origin rpy="0 0 0" xyz="0 0 +0.001"/>
      <geometry>
        <mesh filename="package://abb_barrett_support/meshes/abb_barrett/collision/camera_frame_link.STL"/>
      </geometry>
      <material name="">
        <color rgba="1 1 0 1"/>
      </material>
    </collision>
  </link>
  <link name="FT_sensor_link">
    <inertial>
      <origin rpy="0 0 0" xyz="0 0 0.075 "/>
      <!-- <origin xyz="0.008 0.0043 0.008 " /> -->
      <mass value="0.05"/>
      <inertia ixx="1e-6" ixy="0.0" ixz="0.0" iyy="1e-6" iyz="0.0" izz="1e-6"/>
    </inertial>
    <visual>
      <origin xyz="0 0 0.0"/>
      <geometry>
        <cylinder length="0.02" radius="0.02"/>
      </geometry>
    </visual>
    <collision>
      <origin xyz="0 0 0.0"/>
      <geometry>
        <cylinder length="0.02" radius="0.02"/>
      </geometry>
    </collision>
  </link>
  <link name="tool0"/>
  <!-- end of link list -->
  <!-- joint list -->
  <joint name="frame_abb_link" type="fixed">
    <origin rpy=" 0 1.57079632679 0 " xyz="0.162 -0.291 0.43"/>
    <parent link="base_link_robot"/>
    <child link="base_link"/>
  </joint>
  <joint name="joint_1" type="revolute">
    <origin rpy="0 0 0" xyz="0 0 0"/>
    <parent link="base_link"/>
    <child link="link_1"/>
    <limit effort="0" lower="-2.87979" upper="2.87979" velocity="4.36332"/>
    <axis xyz="0 0 1"/>
    <dynamics damping="0.0" friction="0.0"/>
  </joint>
  <joint name="joint_2" type="revolute">
    <origin rpy=" 0 0 0" xyz="0 0 0.29"/>
    <parent link="link_1"/>
    <child link="link_2"/>
    <limit effort="0" lower="-1.91986" upper="1.91986" velocity="4.36332"/>
    <axis xyz="0 1 0"/>
    <dynamics damping="0.0" friction="0.0"/>
  </joint>
  <joint name="joint_3" type="revolute">
    <origin rpy="0 0 0" xyz="0 0 0.27"/>
    <parent link="link_2"/>
    <child link="link_3"/>
    <limit effort="0" lower="-1.91986" upper="1.22173" velocity="4.36332"/>
    <axis xyz="0 1 0"/>
    <dynamics damping="0.0" friction="0.0"/>
  </joint>
  <joint name="joint_4" type="revolute">
    <origin rpy="0 0 0" xyz="0 0 0.07"/>
    <parent link="link_3"/>
    <child link="link_4"/>
    <limit effort="0" lower="-2.79253" upper="2.79253" velocity="5.58505"/>
    <axis xyz="1 0 0"/>
    <dynamics damping="0.0" friction="0.0"/>
  </joint>
  <joint name="joint_5" type="revolute">
    <origin rpy="0 0 0" xyz="0.302 0 0"/>
    <parent link="link_4"/>
    <child link="link_5"/>
    <limit effort="0" lower="-2.094395" upper="2.094395" velocity="5.58505"/>
    <axis xyz="0 1 0"/>
    <dynamics damping="0.0" friction="0.0"/>
  </joint>
  <joint name="joint_6" type="revolute">
    <origin rpy="0 0 0" xyz="0.072 0 0"/>
    <parent link="link_5"/>
    <child link="link_6"/>
    <limit effort="0" lower="-9.98132" upper="9.98132" velocity="7.33038"/>
    <axis xyz="1 0 0"/>
    <dynamics damping="0.0" friction="0.0"/>
  </joint>
  <joint name="joint6-tool0" type="fixed">
    <parent link="link_6"/>
    <child link="tool0"/>
    <origin rpy="0 0 0" xyz="0 0 0"/>
  </joint>
  <joint name="wheel_1_joint" type="fixed">
    <parent link="base_link_robot"/>
    <child link="wheel_1"/>
    <origin rpy="1.57079632679 0 0" xyz="-0.1 -0.16 -0.29"/>
  </joint>
  <joint name="wheel_2_joint" type="fixed">
    <parent link="base_link_robot"/>
    <child link="wheel_2"/>
    <origin rpy="1.57079632679 0 0" xyz="-0.1 0.15 -0.29"/>
  </joint>
  <joint name="wheel_3_joint" type="fixed">
    <parent link="base_link_robot"/>
    <child link="wheel_3"/>
    <origin rpy="1.57079632679 0 0" xyz="0.2 -0.16 -0.29"/>
  </joint>
  <joint name="wheel_4_joint" type="fixed">
    <parent link="base_link_robot"/>
    <child link="wheel_4"/>
    <origin rpy="1.57079632679 0 0" xyz="0.2 0.15 -0.29"/>
  </joint>
  <joint name="camera_frame_joint" type="revolute">
    <axis xyz="0 1 0"/>
    <origin rpy="0 0 0" xyz="0.171462 -0.010554 0.888943"/>
    <parent link="base_link_robot"/>
    <child link="camera_frame_link"/>
    <limit effort="0" lower="-1.57" upper="1.57" velocity="2"/>
    <axis xyz="1 0 0"/>
    <dynamics damping="0.0" friction="0.0"/>
  </joint>
  <joint name="abb_FT_sensor_joint" type="fixed">
    <origin rpy=" 1.57079632679 -4.71238898038 1.57079632679" xyz="0.01 0 0"/>
    <parent link="link_6"/>
    <child link="FT_sensor_link"/>
  </joint>
  <!-- end of joint list -->
  <!-- ROS base_link to ABB World Coordinates transform -->
  <link name="base"/>
  <joint name="base_link-base" type="fixed">
    <origin rpy="0 0 0" xyz="0 0 0"/>
    <parent link="base_link"/>
    <child link="base"/>
  </joint>
  <!-- transmission list -->
  <transmission name="tran1">
    <type>transmission_interface/SimpleTransmission</type>
    <joint name="joint_1">
      <hardwareInterface>PositionJointInterface</hardwareInterface>
    </joint>
    <actuator name="motor1">
      <mechanicalReduction>1</mechanicalReduction>
    </actuator>
  </transmission>
  <transmission name="tran2">
    <type>transmission_interface/SimpleTransmission</type>
    <joint name="joint_2">
      <hardwareInterface>PositionJointInterface</hardwareInterface>
    </joint>
    <actuator name="motor2">
      <mechanicalReduction>1</mechanicalReduction>
    </actuator>
  </transmission>
  <transmission name="tran3">
    <type>transmission_interface/SimpleTransmission</type>
    <joint name="joint_3">
      <hardwareInterface>PositionJointInterface</hardwareInterface>
    </joint>
    <actuator name="motor3">
      <mechanicalReduction>1</mechanicalReduction>
    </actuator>
  </transmission>
  <transmission name="tran4">
    <type>transmission_interface/SimpleTransmission</type>
    <joint name="joint_4">
      <hardwareInterface>PositionJointInterface</hardwareInterface>
    </joint>
    <actuator name="motor4">
      <mechanicalReduction>1</mechanicalReduction>
    </actuator>
  </transmission>
  <transmission name="tran5">
    <type>transmission_interface/SimpleTransmission</type>
    <joint name="joint_5">
      <hardwareInterface>PositionJointInterface</hardwareInterface>
    </joint>
    <actuator name="motor5">
      <mechanicalReduction>1</mechanicalReduction>
    </actuator>
  </transmission>
  <transmission name="tran6">
    <type>transmission_interface/SimpleTransmission</type>
    <joint name="joint_6">
      <hardwareInterface>PositionJointInterface</hardwareInterface>
    </joint>
    <actuator name="motor6">
      <mechanicalReduction>1</mechanicalReduction>
    </actuator>
  </transmission>
  <transmission name="tran7">
    <type>transmission_interface/SimpleTransmission</type>
    <joint name="camera_frame_joint">
      <hardwareInterface>PositionJointInterface</hardwareInterface>
    </joint>
    <actuator name="motor7">
      <mechanicalReduction>1</mechanicalReduction>
    </actuator>
  </transmission>
  <!-- end of transmission list -->
  <!-- Gazebo-specific link properties -->
  <gazebo reference="base_link">
    <material>Gazebo/Orange</material>
    <turnGravityOff>true</turnGravityOff>
  </gazebo>
  <gazebo reference="link_1">
    <material>Gazebo/Orange</material>
    <turnGravityOff>true</turnGravityOff>
  </gazebo>
  <gazebo reference="link_2">
    <material>Gazebo/Orange</material>
    <turnGravityOff>true</turnGravityOff>
  </gazebo>
  <gazebo reference="link_3">
    <material>Gazebo/Orange</material>
    <turnGravityOff>true</turnGravityOff>
  </gazebo>
  <gazebo reference="link_4">
    <material>Gazebo/Orange</material>
    <turnGravityOff>true</turnGravityOff>
  </gazebo>
  <gazebo reference="link_5">
    <material>Gazebo/Orange</material>
    <turnGravityOff>true</turnGravityOff>
  </gazebo>
  <gazebo reference="link_6">
    <material>Gazebo/Black</material>
    <turnGravityOff>true</turnGravityOff>
  </gazebo>
  <gazebo reference="camera_frame_joint">
    <material>Gazebo/Black</material>
    <turnGravityOff>true</turnGravityOff>
  </gazebo>
  <gazebo reference="FT_sensor_link">
    <material>Gazebo/Black</material>
    <mu1 value="0.3"/>
    <mu2 value="0.3"/>
    <kp value="1000000.0"/>
    <kd value="1.0"/>
    <minDepth value="1.0"/>
  </gazebo>
  <!-- ros_control plugin -->
  <gazebo>
    <plugin filename="libgazebo_ros_control.so" name="gazebo_ros_control">
      <robotNamespace>/</robotNamespace>
      <robotSimType>gazebo_ros_control/DefaultRobotHWSim</robotSimType>
    </plugin>
  </gazebo>
  <!-- Fix robot to Gazebo world -->
  <link name="world"/>
  <joint name="world-base_link-fixed" type="fixed">
    <origin rpy="0 0 0" xyz="0 0 -0.33"/>
    <parent link="base_link_robot"/>
    <child link="world"/>
  </joint>
  <joint name="hokuyo_joint" type="fixed">
    <axis xyz="0 1 0"/>
    <origin rpy="0 0 0" xyz="0.31 0 -0.19"/>
    <parent link="base_link_robot"/>
    <child link="hokuyo_link"/>
  </joint>
  <joint name="FT_sensor_barrett_joint" type="revolute">
    <origin rpy=" 0 0 1.5708 " xyz="0.0 0 0"/>
    <parent link="FT_sensor_link"/>
    <child link="barrett_base_link"/>
    <axis xyz="1 0 0"/>
    <dynamics damping="0.39" friction="0.01"/>
    <limit effort="50.0" lower="0.01" upper="0.01" velocity="50.0"/>
  </joint>
  <transmission name="tran10">
    <type>transmission_interface/SimpleTransmission</type>
    <joint name="FT_sensor_barrett_joint">
      <hardwareInterface>PositionJointInterface</hardwareInterface>
    </joint>
    <actuator name="motor10">
      <mechanicalReduction>1</mechanicalReduction>
    </actuator>
  </transmission>
  <link name="end_effector_link"/>
  <joint name="end_effector_joint" type="fixed">
    <origin rpy=" 0 0 0" xyz="0.12 0 0.0"/>
    <parent link="link_6"/>
    <child link="end_effector_link"/>
  </joint>
  <gazebo reference="FT_sensor_barrett_joint">
    <provideFeedback>true</provideFeedback>
  </gazebo>
  <!-- Enable the Joint Feedback -->
  <gazebo>
    <plugin filename="libgazebo_ros_ft_sensor.so" name="ft_sensor">
      <updateRate>1000.0</updateRate>
      <topicName>/ft_sensor_topic</topicName>
      <jointName>FT_sensor_barrett_joint</jointName>
      <noise>
        <type>gaussian</type>
        <mean>0.0</mean>
        <stddev>0.003</stddev>
          change this to simulate noise 
        
      </noise>
    </plugin>
  </gazebo>
  <joint name="piece_joint" type="fixed">
    <axis xyz="0 0 1"/>
    <origin rpy="1.5708 0 0" xyz="0 0 0.125"/>
    <parent link="palm_frame"/>
    <child link="cylinder_link"/>
  </joint>
  <joint name="cube_joint" type="fixed">
    <axis xyz="0 0 1"/>
    <origin rpy="1.5708 0 0" xyz="0.8 -0.09 0.34"/>
    <parent link="world"/>
    <child link="cube_link"/>
  </joint>
</robot>

