<?xml version="1.0" ?>
<!-- =================================================================================== -->
<!-- |    This document was autogenerated by xacro from husky_ur5.urdf.xacro           | -->
<!-- |    EDITING THIS FILE BY HAND IS NOT RECOMMENDED                                 | -->
<!-- =================================================================================== -->
<robot name="husky_ur5" xmlns:xacro="http://ros.org/wiki/xacro">
  <!-- Base link is the center of the robot's bottom plate -->
  <link name="base_link">
    <visual>
      <origin rpy="0 0 0" xyz="0 0 0"/>
      <geometry>
        <mesh filename="package://husky_description/meshes/base_link.dae"/>
      </geometry>
    </visual>
    <collision>
      <origin rpy="0 0 0" xyz="0.0 0 0.061875"/>
      <geometry>
        <box size="0.9874 0.5709 0.12375"/>
      </geometry>
    </collision>
    <collision>
      <origin rpy="0 0 0" xyz="0 0 0.185625"/>
      <geometry>
        <box size="0.78992 0.5709 0.12375"/>
      </geometry>
    </collision>
  </link>
  <!-- Base footprint is on the ground under the robot -->
  <link name="base_footprint"/>
  <joint name="base_footprint_joint" type="fixed">
    <origin rpy="0 0 0" xyz="0 0 -0.13228"/>
    <parent link="base_link"/>
    <child link="base_footprint"/>
  </joint>
  <!-- Interial link stores the robot's inertial information -->
  <link name="inertial_link">
    <inertial>
      <mass value="46.034"/>
      <origin xyz="-0.00065 -0.085 0.062"/>
      <inertia ixx="0.6022" ixy="-0.02364" ixz="-0.1197" iyy="1.7386" iyz="-0.001544" izz="2.0296"/>
    </inertial>
  </link>
  <joint name="inertial_joint" type="fixed">
    <origin rpy="0 0 0" xyz="0 0 0"/>
    <parent link="base_link"/>
    <child link="inertial_link"/>
  </joint>
  <!-- IMU Link is the standard mounting position for the UM6 IMU.-->
  <!-- Can be modified with environment variables in /etc/ros/setup.bash -->
  <link name="imu_link"/>
  <joint name="imu_joint" type="fixed">
    <origin rpy="0 -1.5708 3.1416" xyz="0.19 0 0.149"/>
    <parent link="base_link"/>
    <child link="imu_link"/>
  </joint>
  <gazebo reference="imu_link">
  </gazebo>
  <link name="front_left_wheel_link">
    <inertial>
      <mass value="2.637"/>
      <origin xyz="0 0 0"/>
      <inertia ixx="0.02467" ixy="0" ixz="0" iyy="0.04411" iyz="0" izz="0.02467"/>
    </inertial>
    <visual>
      <origin rpy="0 0 0" xyz="0 0 0"/>
      <geometry>
        <mesh filename="package://husky_description/meshes/wheel.dae"/>
      </geometry>
    </visual>
    <collision>
      <origin rpy="1.570795 0 0" xyz="0 0 0"/>
      <geometry>
        <cylinder length="0.1143" radius="0.1651"/>
      </geometry>
    </collision>
  </link>
  <gazebo reference="front_left_wheel_link">
    <mu1 value="1.0"/>
    <mu2 value="1.0"/>
    <kp value="10000000.0"/>
    <kd value="1.0"/>
    <fdir1 value="1 0 0"/>
  </gazebo>
  <joint name="front_left_wheel" type="continuous">
    <parent link="base_link"/>
    <child link="front_left_wheel_link"/>
    <origin rpy="0 0 0" xyz="0.256 0.2854 0.03282"/>
    <axis rpy="0 0 0" xyz="0 1 0"/>
  </joint>
  <transmission name="front_left_wheel_trans" type="SimpleTransmission">
    <type>transmission_interface/SimpleTransmission</type>
    <actuator name="front_left_wheel_motor">
      <mechanicalReduction>1</mechanicalReduction>
    </actuator>
    <joint name="front_left_wheel">
      <hardwareInterface>hardware_interface/VelocityJointInterface</hardwareInterface>
    </joint>
  </transmission>
  <link name="front_right_wheel_link">
    <inertial>
      <mass value="2.637"/>
      <origin xyz="0 0 0"/>
      <inertia ixx="0.02467" ixy="0" ixz="0" iyy="0.04411" iyz="0" izz="0.02467"/>
    </inertial>
    <visual>
      <origin rpy="0 0 0" xyz="0 0 0"/>
      <geometry>
        <mesh filename="package://husky_description/meshes/wheel.dae"/>
      </geometry>
    </visual>
    <collision>
      <origin rpy="1.570795 0 0" xyz="0 0 0"/>
      <geometry>
        <cylinder length="0.1143" radius="0.1651"/>
      </geometry>
    </collision>
  </link>
  <gazebo reference="front_right_wheel_link">
    <mu1 value="1.0"/>
    <mu2 value="1.0"/>
    <kp value="10000000.0"/>
    <kd value="1.0"/>
    <fdir1 value="1 0 0"/>
  </gazebo>
  <joint name="front_right_wheel" type="continuous">
    <parent link="base_link"/>
    <child link="front_right_wheel_link"/>
    <origin rpy="0 0 0" xyz="0.256 -0.2854 0.03282"/>
    <axis rpy="0 0 0" xyz="0 1 0"/>
  </joint>
  <transmission name="front_right_wheel_trans" type="SimpleTransmission">
    <type>transmission_interface/SimpleTransmission</type>
    <actuator name="front_right_wheel_motor">
      <mechanicalReduction>1</mechanicalReduction>
    </actuator>
    <joint name="front_right_wheel">
      <hardwareInterface>hardware_interface/VelocityJointInterface</hardwareInterface>
    </joint>
  </transmission>
  <link name="rear_left_wheel_link">
    <inertial>
      <mass value="2.637"/>
      <origin xyz="0 0 0"/>
      <inertia ixx="0.02467" ixy="0" ixz="0" iyy="0.04411" iyz="0" izz="0.02467"/>
    </inertial>
    <visual>
      <origin rpy="0 0 0" xyz="0 0 0"/>
      <geometry>
        <mesh filename="package://husky_description/meshes/wheel.dae"/>
      </geometry>
    </visual>
    <collision>
      <origin rpy="1.570795 0 0" xyz="0 0 0"/>
      <geometry>
        <cylinder length="0.1143" radius="0.1651"/>
      </geometry>
    </collision>
  </link>
  <gazebo reference="rear_left_wheel_link">
    <mu1 value="1.0"/>
    <mu2 value="1.0"/>
    <kp value="10000000.0"/>
    <kd value="1.0"/>
    <fdir1 value="1 0 0"/>
  </gazebo>
  <joint name="rear_left_wheel" type="continuous">
    <parent link="base_link"/>
    <child link="rear_left_wheel_link"/>
    <origin rpy="0 0 0" xyz="-0.256 0.2854 0.03282"/>
    <axis rpy="0 0 0" xyz="0 1 0"/>
  </joint>
  <transmission name="rear_left_wheel_trans" type="SimpleTransmission">
    <type>transmission_interface/SimpleTransmission</type>
    <actuator name="rear_left_wheel_motor">
      <mechanicalReduction>1</mechanicalReduction>
    </actuator>
    <joint name="rear_left_wheel">
      <hardwareInterface>hardware_interface/VelocityJointInterface</hardwareInterface>
    </joint>
  </transmission>
  <link name="rear_right_wheel_link">
    <inertial>
      <mass value="2.637"/>
      <origin xyz="0 0 0"/>
      <inertia ixx="0.02467" ixy="0" ixz="0" iyy="0.04411" iyz="0" izz="0.02467"/>
    </inertial>
    <visual>
      <origin rpy="0 0 0" xyz="0 0 0"/>
      <geometry>
        <mesh filename="package://husky_description/meshes/wheel.dae"/>
      </geometry>
    </visual>
    <collision>
      <origin rpy="1.570795 0 0" xyz="0 0 0"/>
      <geometry>
        <cylinder length="0.1143" radius="0.1651"/>
      </geometry>
    </collision>
  </link>
  <gazebo reference="rear_right_wheel_link">
    <mu1 value="1.0"/>
    <mu2 value="1.0"/>
    <kp value="10000000.0"/>
    <kd value="1.0"/>
    <fdir1 value="1 0 0"/>
  </gazebo>
  <joint name="rear_right_wheel" type="continuous">
    <parent link="base_link"/>
    <child link="rear_right_wheel_link"/>
    <origin rpy="0 0 0" xyz="-0.256 -0.2854 0.03282"/>
    <axis rpy="0 0 0" xyz="0 1 0"/>
  </joint>
  <transmission name="rear_right_wheel_trans" type="SimpleTransmission">
    <type>transmission_interface/SimpleTransmission</type>
    <actuator name="rear_right_wheel_motor">
      <mechanicalReduction>1</mechanicalReduction>
    </actuator>
    <joint name="rear_right_wheel">
      <hardwareInterface>hardware_interface/VelocityJointInterface</hardwareInterface>
    </joint>
  </transmission>
  <!-- Spawn Husky chassis -->
  <link name="top_chassis_link">
    <visual>
      <origin rpy="0 0 0" xyz="0 0 0"/>
      <geometry>
        <mesh filename="package://husky_description/meshes/top_chassis.dae"/>
      </geometry>
    </visual>
  </link>
  <!-- Attach chassis to the robot -->
  <joint name="top_chassis_joint" type="fixed">
    <parent link="base_link"/>
    <child link="top_chassis_link"/>
  </joint>
  <!-- Spawn user rails -->
  <link name="user_rail_link">
    <visual>
      <geometry>
        <mesh filename="package://husky_description/meshes/user_rail.dae"/>
      </geometry>
    </visual>
  </link>
  <!-- Attach user rails to base link -->
  <joint name="user_rail" type="fixed">
    <origin rpy="0 0 0" xyz="0.272 0 0.245"/>
    <parent link="base_link"/>
    <child link="user_rail_link"/>
  </joint>
  <!-- Spawn front bumper link -->
  <link name="front_bumper_link">
    <visual>
      <geometry>
        <mesh filename="package://husky_description/meshes/bumper.dae"/>
      </geometry>
    </visual>
  </link>
  <!-- Attach front bumper -->
  <joint name="front_bumper" type="fixed">
    <origin rpy="0 0 0" xyz="0.48 0 0.091"/>
    <parent link="base_link"/>
    <child link="front_bumper_link"/>
  </joint>
  <!-- Spawn rear bumper link -->
  <link name="rear_bumper_link">
    <visual>
      <geometry>
        <mesh filename="package://husky_description/meshes/bumper.dae"/>
      </geometry>
    </visual>
  </link>
  <!-- Attach rear bumper -->
  <joint name="rear_bumper" type="fixed">
    <origin rpy="0 0 3.14159" xyz="-0.48 0 0.091"/>
    <parent link="base_link"/>
    <child link="rear_bumper_link"/>
  </joint>
  <link name="top_plate_link">
    <visual>
      <origin rpy="0 0 0" xyz="0 0 0"/>
      <geometry>
        <mesh filename="package://husky_description/meshes/top_plate.dae"/>
      </geometry>
    </visual>
    <collision>
      <origin rpy="0 0 0" xyz="0 0 0"/>
      <geometry>
        <mesh filename="package://husky_description/meshes/top_plate.dae"/>
      </geometry>
    </collision>
    <collision>
      <!-- Extra collision tag for widgets on top plate -->
      <geometry>
        <box rpy="0 0 0" size="0.32 0.41 0.09"/>
      </geometry>
    </collision>
  </link>
  <!-- Attach top plate -->
  <joint name="top_plate_joint" type="fixed">
    <parent link="base_link"/>
    <child link="top_plate_link"/>
    <origin rpy="0 0 0" xyz="0.0812 0 0.245"/>
  </joint>
  <!-- Top plate front link -->
  <joint name="top_plate_front_joint" type="fixed">
    <parent link="top_plate_link"/>
    <child link="top_plate_front_link"/>
    <origin rpy="0 0 0" xyz="0.36367 0 0.00639"/>
  </joint>
  <!-- Top plate rear link-->
  <joint name="top_plate_rear_joint" type="fixed">
    <parent link="top_plate_link"/>
    <child link="top_plate_rear_link"/>
    <origin rpy="0 0 0" xyz="-0.36633 0 0.00639"/>
  </joint>
  <link name="top_plate_front_link"/>
  <link name="top_plate_rear_link"/>
  <gazebo>
    <plugin filename="libgazebo_ros_control.so" name="gazebo_ros_control">
      <robotNamespace>/</robotNamespace>
    </plugin>
  </gazebo>
  <gazebo>
    <plugin filename="libhector_gazebo_ros_imu.so" name="imu_controller">
      <robotNamespace>/</robotNamespace>
      <updateRate>50.0</updateRate>
      <bodyName>base_link</bodyName>
      <topicName>imu/data</topicName>
      <accelDrift>0.005 0.005 0.005</accelDrift>
      <accelGaussianNoise>0.005 0.005 0.005</accelGaussianNoise>
      <rateDrift>0.005 0.005 0.005 </rateDrift>
      <rateGaussianNoise>0.005 0.005 0.005 </rateGaussianNoise>
      <headingDrift>0.005</headingDrift>
      <headingGaussianNoise>0.005</headingGaussianNoise>
    </plugin>
  </gazebo>
  <gazebo>
    <plugin filename="libhector_gazebo_ros_gps.so" name="gps_controller">
      <robotNamespace>/</robotNamespace>
      <updateRate>40</updateRate>
      <bodyName>base_link</bodyName>
      <frameId>base_link</frameId>
      <topicName>navsat/fix</topicName>
      <velocityTopicName>navsat/vel</velocityTopicName>
      <referenceLatitude>49.9</referenceLatitude>
      <referenceLongitude>8.9</referenceLongitude>
      <referenceHeading>0</referenceHeading>
      <referenceAltitude>0</referenceAltitude>
      <drift>0.0001 0.0001 0.0001</drift>
    </plugin>
  </gazebo>
  <!-- This file is a placeholder which is included by default from
       husky.urdf.xacro. If a robot is being customized and requires
       additional URDF, set the HUSKY_URDF_EXTRAS environment variable
       to the full path of the file you would like included. -->
  <link name="barrett_base_link">
    <inertial>
      <mass value="0.1"/>
      <origin rpy="0 0 0" xyz="0 0 0"/>
      <inertia ixx="1" ixy="0" ixz="0" iyy="1" iyz="0" izz="1"/>
    </inertial>
    <visual>
      <origin rpy="0 0 0" xyz="0 0 0"/>
      <geometry>
        <mesh filename="package://abb_barrett_description/meshes/base_link.STL"/>
      </geometry>
      <material name="">
        <color rgba="0.752941176470588 0.752941176470588 0.752941176470588 1"/>
      </material>
    </visual>
    <collision>
      <origin rpy="0 0 0" xyz="0 0 0"/>
      <geometry>
        <mesh filename="package://abb_barrett_description/meshes/base_link.STL"/>
      </geometry>
    </collision>
  </link>
  <joint name="palm_joint" type="fixed">
    <!--original is revolute-->
    <origin xyz="0.0 0.0 0.077"/>
    <parent link="barrett_base_link"/>
    <child link="palm_frame"/>
  </joint>
  <link name="palm_frame">
  </link>
  <link name="finger_1_prox_link">
    <inertial>
      <mass value="0.1"/>
      <origin rpy="0 0 0" xyz="0 0 0"/>
      <inertia ixx="1" ixy="0" ixz="0" iyy="1" iyz="0" izz="1"/>
    </inertial>
    <visual>
      <origin rpy="0 0 0" xyz="0 0 0"/>
      <geometry>
        <mesh filename="package://abb_barrett_description/meshes/finger_1_prox_link.STL"/>
      </geometry>
      <material name="">
        <color rgba="0.752941176470588 0.752941176470588 0.752941176470588 1"/>
      </material>
    </visual>
    <collision>
      <origin rpy="0 0 0" xyz="0 0 0"/>
      <geometry>
        <mesh filename="package://abb_barrett_description/meshes/finger_1_prox_link.STL"/>
      </geometry>
    </collision>
  </link>
  <!--joint name="finger_1_prox_joint" type="revolute">
    <origin xyz="0.025 0 0.0415" rpy="0 2.7051E-17 -1.5708" />
    <parent link="barrett_base_link" />
    <child link="finger_1_prox_link" />
    <axis xyz="0 0 -1" />
    <limit lower="0.0" upper="3.141" effort="10000" velocity="0.2" />
   <dynamics damping="10.0" friction="10.0" />
  </joint-->
  <joint name="finger_1_prox_joint" type="revolute">
    <origin rpy="0 2.7051E-17 3.67" xyz="0.025 0 0.0415"/>
    <parent link="barrett_base_link"/>
    <child link="finger_1_prox_link"/>
    <axis xyz="0 0 -1"/>
    <limit effort="10000" lower="0.0" upper="3.141" velocity="0.2"/>
    <dynamics damping="10.0" friction="10.0"/>
  </joint>
  <link name="finger_1_med_link">
    <inertial>
      <mass value="0.1"/>
      <origin rpy="0 0 0" xyz="0 0 0"/>
      <inertia ixx="1" ixy="0" ixz="0" iyy="1" iyz="0" izz="1"/>
    </inertial>
    <visual>
      <origin rpy="3.14159265359 0 0" xyz="0 0 0"/>
      <geometry>
        <mesh filename="package://abb_barrett_description/meshes/finger_1_med_link.STL"/>
      </geometry>
      <material name="">
        <color rgba="0.752941176470588 0.752941176470588 0.752941176470588 1"/>
      </material>
    </visual>
    <collision>
      <origin rpy="3.14159265359 0 0" xyz="0 0 0"/>
      <geometry>
        <mesh filename="package://abb_barrett_description/meshes/finger_1_med_link.STL"/>
      </geometry>
    </collision>
  </link>
  <!--joint
    name="finger_1_med_joint"
    type="revolute">
    <origin xyz="-0.05 0 0.0339" rpy="-1.5708 -8.8281E-17 0" />
    <parent link="finger_1_prox_link" />
    <child link="finger_1_med_link" />
    <axis xyz="0 0 1" />
    <limit lower="0" upper="2.44" effort="10000" velocity="0.2" />
   <dynamics damping="10.0" friction="10.0" />
  </joint-->
  <joint name="finger_1_med_joint" type="revolute">
    <origin rpy="-1.5708 1.5708 0" xyz="-0.05 0 0.0339"/>
    <parent link="finger_1_prox_link"/>
    <child link="finger_1_med_link"/>
    <axis xyz="0 0 1"/>
    <limit effort="10000" lower="0" upper="2.44" velocity="0.2"/>
    <dynamics damping="10.0" friction="10.0"/>
  </joint>
  <link name="finger_1_dist_link">
    <inertial>
      <mass value="0.001"/>
      <origin rpy="0 0 0" xyz="0 0 0"/>
      <inertia ixx="1e-1" ixy="0" ixz="0" iyy="1e-1" iyz="0" izz="1e-1"/>
    </inertial>
    <visual>
      <origin rpy="3.14159265359 0 -0.73" xyz="0 0 0"/>
      <geometry>
        <mesh filename="package://abb_barrett_description/meshes/finger_1_dist_link.STL"/>
      </geometry>
      <material name="">
        <color rgba="0.898039215686275 0.917647058823529 0.929411764705882 1"/>
      </material>
    </visual>
    <collision>
      <origin rpy="3.14159265359 0 -0.73" xyz="0 0 0"/>
      <geometry>
        <mesh filename="package://abb_barrett_description/meshes/finger_1_dist_link.STL"/>
      </geometry>
    </collision>
  </link>
  <joint name="finger_1_dist_joint" type="revolute">
    <!--original is revolute-->
    <origin rpy="1.6787E-18 -3.6382E-15 -6.1073E-33" xyz="-0.069936 -0.003 0"/>
    <parent link="finger_1_med_link"/>
    <child link="finger_1_dist_link"/>
    <axis xyz="0 0 1"/>
    <limit effort="10000" lower="0.6" upper="1.57" velocity="0.2"/>
    <dynamics damping="10.0" friction="10.0"/>
    <mimic joint="finger_1_med_joint" multiplier="0.3" offset="0.75"/>
  </joint>
  <link name="finger_2_prox_link">
    <inertial>
      <mass value="0.1"/>
      <origin rpy="0 0 0" xyz="0 0 0"/>
      <inertia ixx="1" ixy="0" ixz="0" iyy="1" iyz="0" izz="1"/>
    </inertial>
    <visual>
      <origin rpy="0 0 0" xyz="0 0 0"/>
      <geometry>
        <mesh filename="package://abb_barrett_description/meshes/finger_2_prox_link.STL"/>
      </geometry>
      <material name="">
        <color rgba="0.752941176470588 0.752941176470588 0.752941176470588 1"/>
      </material>
    </visual>
    <collision>
      <origin rpy="0 0 0" xyz="0 0 0"/>
      <geometry>
        <mesh filename="package://abb_barrett_description/meshes/finger_2_prox_link.STL"/>
      </geometry>
    </collision>
  </link>
  <!--joint name="finger_2_prox_joint" type="revolute">
    <origin xyz="-0.025 0 0.0415" rpy="0 2.7051E-17 -1.5708" />
    <parent link="barrett_base_link" />
    <child link="finger_2_prox_link" />
    <axis xyz="0 0 1" />
    <limit lower="0" upper="3.141" effort="10000"  velocity="0.2" />
   <dynamics damping="10.0" friction="10.0" />
  </joint-->
  <joint name="finger_2_prox_joint" type="revolute">
    <origin rpy="0 2.7051E-17 -0.52" xyz="-0.025 0 0.0415"/>
    <parent link="barrett_base_link"/>
    <child link="finger_2_prox_link"/>
    <axis xyz="0 0 1"/>
    <limit effort="10000" lower="0" upper="3.141" velocity="0.2"/>
    <dynamics damping="10.0" friction="10.0"/>
  </joint>
  <link name="finger_2_med_link">
    <inertial>
      <mass value="0.1"/>
      <origin rpy="0 0 0" xyz="0 0 0"/>
      <inertia ixx="1" ixy="0" ixz="0" iyy="1" iyz="0" izz="1"/>
    </inertial>
    <visual>
      <origin rpy="3.14159265359 0 0" xyz="0 0 0"/>
      <geometry>
        <mesh filename="package://abb_barrett_description/meshes/finger_2_med_link.STL"/>
      </geometry>
      <material name="">
        <color rgba="0.752941176470588 0.752941176470588 0.752941176470588 1"/>
      </material>
    </visual>
    <collision>
      <origin rpy="3.14159265359 0 0" xyz="0 0 0"/>
      <geometry>
        <mesh filename="package://abb_barrett_description/meshes/finger_2_med_link.STL"/>
      </geometry>
    </collision>
  </link>
  <!--joint
    name="finger_2_med_joint"
    type="revolute">
    <origin xyz="-0.05 0 0.0339" rpy="-1.5708 -8.8281E-17 0" />
    <parent link="finger_2_prox_link" />
    <child link="finger_2_med_link" />
    <axis xyz="0 0 1" />
    <limit lower="0.0" upper="2.44" effort="10000" velocity="0.2" />
   <dynamics damping="10.0" friction="10.0" />
  </joint-->
  <joint name="finger_2_med_joint" type="revolute">
    <origin rpy="-1.5708 1.5708 0" xyz="-0.05 0 0.0339"/>
    <parent link="finger_2_prox_link"/>
    <child link="finger_2_med_link"/>
    <axis xyz="0 0 1"/>
    <limit effort="10000" lower="0.0" upper="2.44" velocity="0.2"/>
    <dynamics damping="10.0" friction="10.0"/>
  </joint>
  <link name="finger_2_dist_link">
    <inertial>
      <mass value="0.001"/>
      <origin rpy="0 0 0" xyz="0 0 0"/>
      <inertia ixx="1e-1" ixy="0" ixz="0" iyy="1e-1" iyz="0" izz="1e-1"/>
    </inertial>
    <visual>
      <origin rpy="3.14159265359 0 -0.73" xyz="0 0 0"/>
      <geometry>
        <mesh filename="package://abb_barrett_description/meshes/finger_2_dist_link.STL"/>
      </geometry>
      <material name="">
        <color rgba="0.898039215686275 0.917647058823529 0.929411764705882 1"/>
      </material>
    </visual>
    <collision>
      <origin rpy="3.14159265359 0 -0.73" xyz="0 0 0"/>
      <geometry>
        <mesh filename="package://abb_barrett_description/meshes/finger_2_dist_link.STL"/>
      </geometry>
    </collision>
  </link>
  <joint name="finger_2_dist_joint" type="revolute">
    <!--original is revolute-->
    <origin rpy="-3.1382E-17 -2.3229E-16 0" xyz="-0.069917 -0.0034087 0"/>
    <parent link="finger_2_med_link"/>
    <child link="finger_2_dist_link"/>
    <axis xyz="0 0 1"/>
    <limit effort="10000" lower="0.6" upper="1.57" velocity="0.2"/>
    <dynamics damping="10.0" friction="10.0"/>
    <mimic joint="finger_2_med_joint" multiplier="0.3" offset="0.75"/>
  </joint>
  <link name="finger_3_med_link">
    <inertial>
      <mass value="0.1"/>
      <origin rpy="0 0 0" xyz="-0.05 0 0"/>
      <inertia ixx="1" ixy="0" ixz="0" iyy="1" iyz="0" izz="1"/>
    </inertial>
    <visual>
      <origin rpy="3.14159265359 0 0" xyz="0 0 0"/>
      <geometry>
        <mesh filename="package://abb_barrett_description/meshes/finger_3_med_link.STL"/>
      </geometry>
      <material name="">
        <color rgba="0.752941176470588 0.752941176470588 0.752941176470588 1"/>
      </material>
    </visual>
    <collision>
      <origin rpy="3.14159265359 0 0" xyz="0 0 0"/>
      <geometry>
        <mesh filename="package://abb_barrett_description/meshes/finger_3_med_link.STL"/>
      </geometry>
    </collision>
  </link>
  <!--joint
    name="finger_3_med_joint"
    type="revolute">
    <origin
      xyz="0 -0.05 0.0754"
      rpy="-1.5708 6.123E-17 1.5708" />
    <parent
      link="barrett_base_link" />
    <child
      link="finger_3_med_link" />
    <axis
      xyz="0 0 1" />
    <limit
      lower="0.0"
      upper="2.44"
      effort="10000"
      velocity="0.2" />
   <dynamics damping="10.0" friction="10.0" />
  </joint-->
  <joint name="finger_3_med_joint" type="revolute">
    <origin rpy="-1.5708 1.5708 1.5708" xyz="0 -0.05 0.0754"/>
    <parent link="barrett_base_link"/>
    <child link="finger_3_med_link"/>
    <axis xyz="0 0 1"/>
    <limit effort="10000" lower="0.0" upper="2.44" velocity="0.2"/>
    <dynamics damping="10.0" friction="10.0"/>
  </joint>
  <link name="finger_3_dist_link">
    <inertial>
      <mass value="0.1"/>
      <origin rpy="0 0 0" xyz="-0.04 0 0"/>
      <inertia ixx="1" ixy="0" ixz="0" iyy="1" iyz="0" izz="1"/>
    </inertial>
    <visual>
      <origin rpy="3.14159265359 0 -0.73" xyz="0 0 0"/>
      <geometry>
        <mesh filename="package://abb_barrett_description/meshes/finger_3_dist_link.STL"/>
      </geometry>
      <material name="">
        <color rgba="0.898039215686275 0.917647058823529 0.929411764705882 1"/>
      </material>
    </visual>
    <collision>
      <origin rpy="3.14159265359 0 -0.73" xyz="0 0 0"/>
      <geometry>
        <mesh filename="package://abb_barrett_description/meshes/finger_3_dist_link.STL"/>
      </geometry>
    </collision>
  </link>
  <joint name="finger_3_dist_joint" type="revolute">
    <!--original is revolute-->
    <origin rpy="6.0427E-17 -6.7283E-18 -4.0657E-34" xyz="-0.069936 -0.003 0"/>
    <parent link="finger_3_med_link"/>
    <child link="finger_3_dist_link"/>
    <axis xyz="0 0 1"/>
    <limit effort="10000" lower="0.6" upper="1.57" velocity="0.2"/>
    <dynamics damping="10.0" friction="10.0"/>
    <mimic joint="finger_3_med_joint" multiplier="0.3" offset="0.75"/>
  </joint>
  <transmission name="tran11">
    <type>transmission_interface/SimpleTransmission</type>
    <joint name="finger_1_med_joint">
      <hardwareInterface>PositionJointInterface</hardwareInterface>
    </joint>
    <actuator name="motor11">
      <hardwareInterface>PositionJointInterface</hardwareInterface>
      <mechanicalReduction>1</mechanicalReduction>
    </actuator>
  </transmission>
  <transmission name="tran12">
    <type>transmission_interface/SimpleTransmission</type>
    <joint name="finger_1_dist_joint">
      <hardwareInterface>PositionJointInterface</hardwareInterface>
    </joint>
    <actuator name="motor12">
      <hardwareInterface>PositionJointInterface</hardwareInterface>
      <mechanicalReduction>1</mechanicalReduction>
    </actuator>
  </transmission>
  <transmission name="tran13">
    <type>transmission_interface/SimpleTransmission</type>
    <joint name="finger_2_med_joint">
      <hardwareInterface>PositionJointInterface</hardwareInterface>
    </joint>
    <actuator name="motor13">
      <hardwareInterface>PositionJointInterface</hardwareInterface>
      <mechanicalReduction>1</mechanicalReduction>
    </actuator>
  </transmission>
  <transmission name="tran14">
    <type>transmission_interface/SimpleTransmission</type>
    <joint name="finger_2_dist_joint">
      <hardwareInterface>PositionJointInterface</hardwareInterface>
    </joint>
    <actuator name="motor14">
      <hardwareInterface>PositionJointInterface</hardwareInterface>
      <mechanicalReduction>10</mechanicalReduction>
    </actuator>
  </transmission>
  <transmission name="tran15">
    <type>transmission_interface/SimpleTransmission</type>
    <joint name="finger_3_med_joint">
      <hardwareInterface>PositionJointInterface</hardwareInterface>
    </joint>
    <actuator name="motor15">
      <hardwareInterface>PositionJointInterface</hardwareInterface>
      <mechanicalReduction>1</mechanicalReduction>
    </actuator>
  </transmission>
  <transmission name="tran16">
    <type>transmission_interface/SimpleTransmission</type>
    <joint name="finger_3_dist_joint">
      <hardwareInterface>PositionJointInterface</hardwareInterface>
    </joint>
    <actuator name="motor16">
      <hardwareInterface>PositionJointInterface</hardwareInterface>
      <mechanicalReduction>1</mechanicalReduction>
    </actuator>
  </transmission>
  <transmission name="tran17">
    <type>transmission_interface/SimpleTransmission</type>
    <joint name="finger_1_prox_joint">
      <hardwareInterface>PositionJointInterface</hardwareInterface>
    </joint>
    <actuator name="motor17">
      <hardwareInterface>PositionJointInterface</hardwareInterface>
      <mechanicalReduction>1</mechanicalReduction>
    </actuator>
  </transmission>
  <transmission name="tran18">
    <type>transmission_interface/SimpleTransmission</type>
    <joint name="finger_2_prox_joint">
      <hardwareInterface>PositionJointInterface</hardwareInterface>
    </joint>
    <actuator name="motor18">
      <hardwareInterface>PositionJointInterface</hardwareInterface>
      <mechanicalReduction>1</mechanicalReduction>
    </actuator>
  </transmission>
  <!-- base_link -->
  <gazebo reference="barrett_base_link">
    <material>Gazebo/Grey</material>
    <turnGravityOff>true</turnGravityOff>
  </gazebo>
  <!-- finger_1_prox_link -->
  <gazebo reference="finger_1_prox_link">
    <material>Gazebo/Grey</material>
    <turnGravityOff>true</turnGravityOff>
    <mu1 value="1500.0"/>
    <mu2 value="1500.0"/>
    <kp value="1000000.0"/>
    <kd value="1.0"/>
  </gazebo>
  <gazebo reference="finger_1_prox_joint">
    <stopKd value="1.0"/>
    <stopKp value="10000000.0"/>
    <fudgeFactor value="1.0"/>
    <provideFeedback value="true"/>
  </gazebo>
  <!-- finger_1_med_link -->
  <gazebo reference="finger_1_med_link">
    <turnGravityOff>true</turnGravityOff>
    <mu1 value="1500.0"/>
    <mu2 value="1500.0"/>
    <kp value="1000000.0"/>
    <kd value="1.0"/>
    <material>Gazebo/Black</material>
  </gazebo>
  <gazebo reference="finger_1_med_joint">
    <stopKd value="1.0"/>
    <stopKp value="10000000.0"/>
    <fudgeFactor value="1.0"/>
    <provideFeedback value="true"/>
  </gazebo>
  <!-- finger_1_dist_link -->
  <gazebo reference="finger_1_dist_link">
    <turnGravityOff>true</turnGravityOff>
    <mu1 value="1500.0"/>
    <mu2 value="1500.0"/>
    <kp value="1000000.0"/>
    <kd value="1.0"/>
    <material>Gazebo/Grey</material>
  </gazebo>
  <gazebo reference="finger_1_dist_joint">
    <stopKd value="1.0"/>
    <stopKp value="10000000.0"/>
    <fudgeFactor value="1.0"/>
    <provideFeedback value="true"/>
  </gazebo>
  <!-- finger_2_prox_link -->
  <gazebo reference="finger_2_prox_link">
    <turnGravityOff>true</turnGravityOff>
    <mu1 value="1500.0"/>
    <mu2 value="1500.0"/>
    <kp value="1000000.0"/>
    <kd value="1.0"/>
    <material>Gazebo/Grey</material>
  </gazebo>
  <!-- finger_2_med_link -->
  <gazebo reference="finger_2_med_link">
    <turnGravityOff>true</turnGravityOff>
    <mu1 value="1500.0"/>
    <mu2 value="1500.0"/>
    <kp value="1000000.0"/>
    <kd value="1.0"/>
    <material>Gazebo/Black</material>
  </gazebo>
  <!-- finger_2_dist_link -->
  <gazebo reference="finger_2_dist_link">
    <turnGravityOff>true</turnGravityOff>
    <mu1 value="1500.0"/>
    <mu2 value="1500.0"/>
    <kp value="1000000.0"/>
    <kd value="1.0"/>
    <material>Gazebo/Grey</material>
  </gazebo>
  <!-- finger_3_med_link -->
  <gazebo reference="finger_3_med_link">
    <turnGravityOff>true</turnGravityOff>
    <mu1 value="1500.0"/>
    <mu2 value="1500.0"/>
    <kp value="1000000.0"/>
    <kd value="1.0"/>
    <material>Gazebo/Black</material>
  </gazebo>
  <!-- finger_3_dist_link -->
  <gazebo reference="finger_3_dist_link">
    <turnGravityOff>true</turnGravityOff>
    <mu1 value="1500.0"/>
    <mu2 value="1500.0"/>
    <kp value="1000000.0"/>
    <kd value="1.0"/>
    <material>Gazebo/Grey</material>
  </gazebo>
  <gazebo>
    <plugin filename="libgazebo_ros_p3d.so" name="p3d_barrett_gripper_palm_controller">
      <alwaysOn>true</alwaysOn>
      <updateRate>100.0</updateRate>
      <bodyName>barrett_base_link</bodyName>
      <topicName>barrett_palm_pose_ground_truth</topicName>
      <xyzOffsets>0 0 0</xyzOffsets>
      <rpyOffsets>0 0 0</rpyOffsets>
      <gaussianNoise>0.0</gaussianNoise>
      <frameName>world</frameName>
    </plugin>
    <!-- a formal implementation of grasp hack in gazebo with fixed joint -->
    <gripper name="barrett_grasp_hack">
      <grasp_check>
        <attach_steps>20</attach_steps>
        <detach_steps>40</detach_steps>
        <min_contact_count>2</min_contact_count>
      </grasp_check>
      <gripper_link>finger_1_prox_link</gripper_link>
      <gripper_link>finger_2_prox_link</gripper_link>
      <palm_link>barrett_base_link</palm_link>
    </gripper>
  </gazebo>
  <gazebo>
    <plugin filename="libgazebo_mimic_plugin.so" name="mimic_plugin">
      <joint>finger_1_med_joint</joint>
      <mimicJoint>finger_1_dist_joint</mimicJoint>
      <multiplier>1.0</multiplier>
    </plugin>
  </gazebo>
  <gazebo>
    <plugin filename="libgazebo_mimic_plugin.so" name="mimic_plugin">
      <joint>finger_2_med_joint</joint>
      <mimicJoint>finger_2_dist_joint</mimicJoint>
      <multiplier>1.0</multiplier>
    </plugin>
  </gazebo>
  <gazebo>
    <plugin filename="libgazebo_mimic_plugin.so" name="mimic_plugin">
      <joint>finger_3_med_joint</joint>
      <mimicJoint>finger_3_dist_joint</mimicJoint>
      <multiplier>1.0</multiplier>
    </plugin>
  </gazebo>
  <!--<gazebo>
    <plugin name="gazebo_ros_control" filename="libgazebo_ros_control.so">
      <robotNamespace>/</robotNamespace>
      <robotSimType>gazebo_ros_control/DefaultRobotHWSim</robotSimType>
    </plugin>
  </gazebo>-->
  <gazebo>
    <plugin filename="libgazebo_ros_joint_pose_trajectory.so" name="gazebo_ros_joint_trajectory">
      <robotNamespace>/</robotNamespace>
      <alwaysOn>true</alwaysOn>
      <updateRate>100.0</updateRate>
    </plugin>
  </gazebo>
  <!-- measured from model -->
  <!--property name="shoulder_height" value="0.089159" /-->
  <!--property name="shoulder_offset" value="0.13585" /-->
  <!-- shoulder_offset - elbow_offset + wrist_1_length = 0.10915 -->
  <!--property name="upper_arm_length" value="0.42500" /-->
  <!--property name="elbow_offset" value="0.1197" /-->
  <!-- CAD measured -->
  <!--property name="forearm_length" value="0.39225" /-->
  <!--property name="wrist_1_length" value="0.093" /-->
  <!-- CAD measured -->
  <!--property name="wrist_2_length" value="0.09465" /-->
  <!-- In CAD this distance is 0.930, but in the spec it is 0.09465 -->
  <!--property name="wrist_3_length" value="0.0823" /-->
  <!-- manually measured -->
  <link name="urbase_link">
    <visual>
      <geometry>
        <mesh filename="package://ur_description/meshes/ur5/visual/base.dae"/>
      </geometry>
      <material name="LightGrey">
        <color rgba="0.7 0.7 0.7 1.0"/>
      </material>
    </visual>
    <collision>
      <geometry>
        <mesh filename="package://ur_description/meshes/ur5/collision/base.stl"/>
      </geometry>
    </collision>
    <inertial>
      <mass value="4.0"/>
      <origin rpy="0 0 0" xyz="0.0 0.0 0.0"/>
      <inertia ixx="0.00443333156" ixy="0.0" ixz="0.0" iyy="0.00443333156" iyz="0.0" izz="0.0072"/>
    </inertial>
  </link>
  <joint name="urshoulder_pan_joint" type="revolute">
    <parent link="urbase_link"/>
    <child link="urshoulder_link"/>
    <origin rpy="0.0 0.0 0.0" xyz="0.0 0.0 0.089159"/>
    <axis xyz="0 0 1"/>
    <limit effort="150.0" lower="-6.28318530718" upper="6.28318530718" velocity="3.15"/>
    <dynamics damping="0.0" friction="0.0"/>
  </joint>
  <link name="urshoulder_link">
    <visual>
      <geometry>
        <mesh filename="package://ur_description/meshes/ur5/visual/shoulder.dae"/>
      </geometry>
      <material name="LightGrey">
        <color rgba="0.7 0.7 0.7 1.0"/>
      </material>
    </visual>
    <collision>
      <geometry>
        <mesh filename="package://ur_description/meshes/ur5/collision/shoulder.stl"/>
      </geometry>
    </collision>
    <inertial>
      <mass value="3.7"/>
      <origin rpy="0 0 0" xyz="0.0 0.0 0.0"/>
      <inertia ixx="0.010267495893" ixy="0.0" ixz="0.0" iyy="0.010267495893" iyz="0.0" izz="0.00666"/>
    </inertial>
  </link>
  <joint name="urshoulder_lift_joint" type="revolute">
    <parent link="urshoulder_link"/>
    <child link="urupper_arm_link"/>
    <origin rpy="0.0 1.57079632679 0.0" xyz="0.0 0.13585 0.0"/>
    <axis xyz="0 1 0"/>
    <limit effort="150.0" lower="-6.28318530718" upper="6.28318530718" velocity="3.15"/>
    <dynamics damping="0.0" friction="0.0"/>
  </joint>
  <link name="urupper_arm_link">
    <visual>
      <geometry>
        <mesh filename="package://ur_description/meshes/ur5/visual/upperarm.dae"/>
      </geometry>
      <material name="LightGrey">
        <color rgba="0.7 0.7 0.7 1.0"/>
      </material>
    </visual>
    <collision>
      <geometry>
        <mesh filename="package://ur_description/meshes/ur5/collision/upperarm.stl"/>
      </geometry>
    </collision>
    <inertial>
      <mass value="8.393"/>
      <origin rpy="0 0 0" xyz="0.0 0.0 0.28"/>
      <inertia ixx="0.22689067591" ixy="0.0" ixz="0.0" iyy="0.22689067591" iyz="0.0" izz="0.0151074"/>
    </inertial>
  </link>
  <joint name="urelbow_joint" type="revolute">
    <parent link="urupper_arm_link"/>
    <child link="urforearm_link"/>
    <origin rpy="0.0 0.0 0.0" xyz="0.0 -0.1197 0.425"/>
    <axis xyz="0 1 0"/>
    <limit effort="150.0" lower="-3.14159265359" upper="3.14159265359" velocity="3.15"/>
    <dynamics damping="0.0" friction="0.0"/>
  </joint>
  <link name="urforearm_link">
    <visual>
      <geometry>
        <mesh filename="package://ur_description/meshes/ur5/visual/forearm.dae"/>
      </geometry>
      <material name="LightGrey">
        <color rgba="0.7 0.7 0.7 1.0"/>
      </material>
    </visual>
    <collision>
      <geometry>
        <mesh filename="package://ur_description/meshes/ur5/collision/forearm.stl"/>
      </geometry>
    </collision>
    <inertial>
      <mass value="2.275"/>
      <origin rpy="0 0 0" xyz="0.0 0.0 0.25"/>
      <inertia ixx="0.049443313556" ixy="0.0" ixz="0.0" iyy="0.049443313556" iyz="0.0" izz="0.004095"/>
    </inertial>
  </link>
  <joint name="urwrist_1_joint" type="revolute">
    <parent link="urforearm_link"/>
    <child link="urwrist_1_link"/>
    <origin rpy="0.0 1.57079632679 0.0" xyz="0.0 0.0 0.39225"/>
    <axis xyz="0 1 0"/>
    <limit effort="28.0" lower="-6.28318530718" upper="6.28318530718" velocity="3.2"/>
    <dynamics damping="0.0" friction="0.0"/>
  </joint>
  <link name="urwrist_1_link">
    <visual>
      <geometry>
        <mesh filename="package://ur_description/meshes/ur5/visual/wrist1.dae"/>
      </geometry>
      <material name="LightGrey">
        <color rgba="0.7 0.7 0.7 1.0"/>
      </material>
    </visual>
    <collision>
      <geometry>
        <mesh filename="package://ur_description/meshes/ur5/collision/wrist1.stl"/>
      </geometry>
    </collision>
    <inertial>
      <mass value="1.219"/>
      <origin rpy="0 0 0" xyz="0.0 0.0 0.0"/>
      <inertia ixx="0.111172755531" ixy="0.0" ixz="0.0" iyy="0.111172755531" iyz="0.0" izz="0.21942"/>
    </inertial>
  </link>
  <joint name="urwrist_2_joint" type="revolute">
    <parent link="urwrist_1_link"/>
    <child link="urwrist_2_link"/>
    <origin rpy="0.0 0.0 0.0" xyz="0.0 0.093 0.0"/>
    <axis xyz="0 0 1"/>
    <limit effort="28.0" lower="-6.28318530718" upper="6.28318530718" velocity="3.2"/>
    <dynamics damping="0.0" friction="0.0"/>
  </joint>
  <link name="urwrist_2_link">
    <visual>
      <geometry>
        <mesh filename="package://ur_description/meshes/ur5/visual/wrist2.dae"/>
      </geometry>
      <material name="LightGrey">
        <color rgba="0.7 0.7 0.7 1.0"/>
      </material>
    </visual>
    <collision>
      <geometry>
        <mesh filename="package://ur_description/meshes/ur5/collision/wrist2.stl"/>
      </geometry>
    </collision>
    <inertial>
      <mass value="1.219"/>
      <origin rpy="0 0 0" xyz="0.0 0.0 0.0"/>
      <inertia ixx="0.111172755531" ixy="0.0" ixz="0.0" iyy="0.111172755531" iyz="0.0" izz="0.21942"/>
    </inertial>
  </link>
  <joint name="urwrist_3_joint" type="revolute">
    <parent link="urwrist_2_link"/>
    <child link="urwrist_3_link"/>
    <origin rpy="0.0 0.0 0.0" xyz="0.0 0.0 0.09465"/>
    <axis xyz="0 1 0"/>
    <limit effort="28.0" lower="-6.28318530718" upper="6.28318530718" velocity="3.2"/>
    <dynamics damping="0.0" friction="0.0"/>
  </joint>
  <link name="urwrist_3_link">
    <visual>
      <geometry>
        <mesh filename="package://ur_description/meshes/ur5/visual/wrist3.dae"/>
      </geometry>
      <material name="LightGrey">
        <color rgba="0.7 0.7 0.7 1.0"/>
      </material>
    </visual>
    <collision>
      <geometry>
        <mesh filename="package://ur_description/meshes/ur5/collision/wrist3.stl"/>
      </geometry>
    </collision>
    <inertial>
      <mass value="0.1879"/>
      <origin rpy="0 0 0" xyz="0.0 0.0 0.0"/>
      <inertia ixx="0.0171364731454" ixy="0.0" ixz="0.0" iyy="0.0171364731454" iyz="0.0" izz="0.033822"/>
    </inertial>
  </link>
  <joint name="uree_fixed_joint" type="fixed">
    <parent link="urwrist_3_link"/>
    <child link="uree_link"/>
    <origin rpy="0.0 0.0 1.57079632679" xyz="0.0 0.0823 0.0"/>
  </joint>
  <link name="uree_link">
    <collision>
      <geometry>
        <box size="0.01 0.01 0.01"/>
      </geometry>
      <origin rpy="0 0 0" xyz="-0.01 0 0"/>
    </collision>
  </link>
  <transmission name="urshoulder_pan_trans">
    <type>transmission_interface/SimpleTransmission</type>
    <joint name="urshoulder_pan_joint">
      <hardwareInterface>hardware_interface/PositionJointInterface</hardwareInterface>
    </joint>
    <actuator name="urshoulder_pan_motor">
      <mechanicalReduction>1</mechanicalReduction>
    </actuator>
  </transmission>
  <transmission name="urshoulder_lift_trans">
    <type>transmission_interface/SimpleTransmission</type>
    <joint name="urshoulder_lift_joint">
      <hardwareInterface>hardware_interface/PositionJointInterface</hardwareInterface>
    </joint>
    <actuator name="urshoulder_lift_motor">
      <mechanicalReduction>1</mechanicalReduction>
    </actuator>
  </transmission>
  <transmission name="urelbow_trans">
    <type>transmission_interface/SimpleTransmission</type>
    <joint name="urelbow_joint">
      <hardwareInterface>hardware_interface/PositionJointInterface</hardwareInterface>
    </joint>
    <actuator name="urelbow_motor">
      <mechanicalReduction>1</mechanicalReduction>
    </actuator>
  </transmission>
  <transmission name="urwrist_1_trans">
    <type>transmission_interface/SimpleTransmission</type>
    <joint name="urwrist_1_joint">
      <hardwareInterface>hardware_interface/PositionJointInterface</hardwareInterface>
    </joint>
    <actuator name="urwrist_1_motor">
      <mechanicalReduction>1</mechanicalReduction>
    </actuator>
  </transmission>
  <transmission name="urwrist_2_trans">
    <type>transmission_interface/SimpleTransmission</type>
    <joint name="urwrist_2_joint">
      <hardwareInterface>hardware_interface/PositionJointInterface</hardwareInterface>
    </joint>
    <actuator name="urwrist_2_motor">
      <mechanicalReduction>1</mechanicalReduction>
    </actuator>
  </transmission>
  <transmission name="urwrist_3_trans">
    <type>transmission_interface/SimpleTransmission</type>
    <joint name="urwrist_3_joint">
      <hardwareInterface>hardware_interface/PositionJointInterface</hardwareInterface>
    </joint>
    <actuator name="urwrist_3_motor">
      <mechanicalReduction>1</mechanicalReduction>
    </actuator>
  </transmission>
  <gazebo reference="urshoulder_link">
    <selfCollide>true</selfCollide>
  </gazebo>
  <gazebo reference="urupper_arm_link">
    <selfCollide>true</selfCollide>
  </gazebo>
  <gazebo reference="urforearm_link">
    <selfCollide>true</selfCollide>
  </gazebo>
  <gazebo reference="urwrist_1_link">
    <selfCollide>true</selfCollide>
  </gazebo>
  <gazebo reference="urwrist_3_link">
    <selfCollide>true</selfCollide>
  </gazebo>
  <gazebo reference="urwrist_2_link">
    <selfCollide>true</selfCollide>
  </gazebo>
  <gazebo reference="uree_link">
    <selfCollide>true</selfCollide>
  </gazebo>
  <!-- ROS base_link to UR 'Base' Coordinates transform -->
  <link name="urbase"/>
  <joint name="urbase_link-base_fixed_joint" type="fixed">
    <!-- NOTE: this rotation is only needed as long as base_link itself is
                 not corrected wrt the real robot (ie: rotated over 180
                 degrees)
      -->
    <origin rpy="0 0 -3.14159265359" xyz="0 0 0"/>
    <parent link="urbase_link"/>
    <child link="urbase"/>
  </joint>
  <!-- Frame coincident with all-zeros TCP on UR controller -->
  <link name="urtool0"/>
  <joint name="urwrist_3_link-tool0_fixed_joint" type="fixed">
    <origin rpy="-1.57079632679 0 0" xyz="0 0.0823 0"/>
    <parent link="urwrist_3_link"/>
    <child link="urtool0"/>
  </joint>
  <!-- Fix robot to Gazebo world-->
  <link name="world"/>
  <joint name="world-base_link-fixed" type="fixed">
    <origin rpy="0 0 0" xyz="0 0 0.33"/>
    <parent link="world"/>
    <child link="base_link"/>
  </joint>
   &gt;
  
  
  <joint name="husky_ur5_joint" type="fixed">
    <axis xyz="0 1 0"/>
    <origin rpy="0 0 0" xyz="0.25 0 0.015"/>
    <parent link="top_plate_link"/>
    <child link="urbase_link"/>
  </joint>
  <joint name="ur5_robotiq_joint" type="fixed">
    <axis xyz="0 1 0"/>
    <origin rpy="0 1.570795  0" xyz="0.0015 0 0"/>
    <parent link="uree_link"/>
    <child link="barrett_base_link"/>
  </joint>
</robot>
